Workbook

Sheet Lapse_data
A1: 1st of Commencement month (DD/MM/YYYY) | B1: Lapses in Month 1 | C1: Lapses in Month 2 | D1: Lapses in Month 3 | E1: Lapses in Month 4 | F1: Lapses in Month 5 | G1: Lapses in Month 6 | H1: Lapses in Month 7 | I1: Lapses in Month 8 | J1: Lapses in Month 9 | K1: Lapses in Month 10 | L1: Lapses in Month 11 | M1: Lapses in Month 12 | N1: Lapses in Month 13 | O1: Lapses in Month 14 | P1: Lapses in Month 15 | Q1: Lapses in Month 16 | R1: Lapses in Month 17 | S1: Lapses in Month 18 | T1: Lapses in Month 19 | U1: Lapses in Month 20 | V1: Lapses in Month 21 | W1: Lapses in Month 22 | X1: Lapses in Month 23 | Y1: Lapses in Month 24 | Z1: Lapses in Month 25 | AA1: Lapses in Month 26 | AB1: Lapses in Month 27 | AC1: Lapses in Month 28 | AD1: Lapses in Month 29 | AE1: Lapses in Month 30 | AF1: Lapses in Month 31 | AG1: Lapses in Month 32 | AH1: Lapses in Month 33 | AI1: Lapses in Month 34 | AJ1: Lapses in Month 35 | AK1: Lapses in Month 36 | AL1: Lapses in Month 37 | AM1: Lapses in Month 38 | AN1: Lapses in Month 39 | AO1: Lapses in Month 40 | AP1: Lapses in Month 41 | AQ1: Lapses in Month 42 | AR1: Lapses in Month 43 | AS1: Lapses in Month 44 | AT1: Lapses in Month 45 | AU1: Lapses in Month 46 | AV1: Lapses in Month 47 | AW1: Lapses in Month 48 | AX1: Lapses in Month 49 | AY1: Lapses in Month 50 | AZ1: Lapses in Month 51 | BA1: Lapses in Month 52 | BB1: Lapses in Month 53 | BC1: Lapses in Month 54 | BD1: Lapses in Month 55 | BE1: Lapses in Month 56 | BF1: Lapses in Month 57 | BG1: Lapses in Month 58 | BH1: Lapses in Month 59 | BI1: Lapses in Month 60 | BJ1: Lapses in Month 61 | BK1: Lapses in Month 62 | BL1: Lapses in Month 63 | BM1: Lapses in Month 64 | BN1: Lapses in Month 65 | BO1: Lapses in Month 66 | BP1: Lapses in Month 67 | BQ1: Lapses in Month 68 | BR1: Lapses in Month 69 | BS1: Lapses in Month 70 | BT1: Lapses in Month 71 | BU1: Lapses in Month 72 | BV1: Lapses in Month 73 | BW1: Lapses in Month 74 | BX1: Lapses in Month 75 | BY1: Lapses in Month 76 | BZ1: Lapses in Month 77 | CA1: Lapses in Month 78 | CB1: Lapses in Month 79 | CC1: Lapses in Month 80 | CD1: Lapses in Month 81 | CE1: Lapses in Month 82 | CF1: Lapses in Month 83 | CG1: Lapses in Month 84 | CH1: Lapses in Month 85 | CI1: Lapses in Month 86 | CJ1: Lapses in Month 87 | CK1: Lapses in Month 88 | CL1: Lapses in Month 89 | CM1: Lapses in Month 90 | CN1: Lapses in Month 91 | CO1: Lapses in Month 92 | CP1: Lapses in Month 93 | CQ1: Lapses in Month 94 | CR1: Lapses in Month 95 | CS1: Lapses in Month 96 | CT1: Lapses in Month 97 | CU1: Lapses in Month 98 | CV1: Lapses in Month 99 | CW1: Lapses in Month 100 | CX1: Lapses in Month 101 | CY1: Lapses in Month 102 | CZ1: Lapses in Month 103 | DA1: Lapses in Month 104 | DB1: Lapses in Month 105 | DC1: Lapses in Month 106 | DD1: Lapses in Month 107 | DE1: Lapses in Month 108 | DF1: Lapses in Month 109 | DG1: Lapses in Month 110 | DH1: Lapses in Month 111 | DI1: Lapses in Month 112 | DJ1: Lapses in Month 113 | DK1: Lapses in Month 114 | DL1: Lapses in Month 115 | DM1: Lapses in Month 116 | DN1: Lapses in Month 117 | DO1: Lapses in Month 118 | DP1: Lapses in Month 119 | DQ1: Lapses in Month 120 | DR1: Year | DS1: Lapses_Y2
A2: 42005 | B2: 59 | C2: 98 | D2: 56 | E2: 79 | F2: 58 | G2: 34 | H2: 42 | I2: 32 | J2: 30 | K2: 30 | L2: 23 | M2: 16 | N2: 17 | O2: 15 | P2: 13 | Q2: 8 | R2: 17 | S2: 9 | T2: 16 | U2: 10 | V2: 15 | W2: 11 | X2: 11 | Y2: 11 | Z2: 8 | AA2: 6 | AB2: 8 | AC2: 11 | AD2: 8 | AE2: 4 | AF2: 4 | AG2: 7 | AH2: 6 | AI2: 4 | AJ2: 4 | AK2: 5 | AL2: 8 | AM2: 9 | AN2: 6 | AO2: 10 | AP2: 2 | AQ2: 10 | AR2: 4 | AS2: 5 | AT2: 6 | AU2: 6 | AV2: 6 | AW2: 2 | AX2: 4 | AY2: 7 | AZ2: 4 | BA2: 4 | BB2: 1 | BC2: 7 | BD2: 3 | BE2: 1 | BF2: 2 | BG2: 5 | BH2: 2 | BI2: 4 | BJ2: 2 | BK2: 4 | BL2: 3 | BM2: 1 | BN2: 2 | BO2: 2 | BP2: 4 | BQ2: 0 | BR2: 1 | BS2: 4 | BT2: 3 | BU2: 2 | BV2: 0 | BW2: 3 | BX2: 2 | BY2: 3 | BZ2: 7 | CA2: 2 | CB2: 2 | CC2: 3 | CD2: 3 | CE2: 0 | CF2: 2 | CG2: 0 | CH2: 1 | CI2: 0 | CJ2: 2 | CK2: 1 | CL2: 3 | CM2: 2 | CN2: 0 | CO2: 3 | CP2: 1 | CQ2: 3 | CR2: 1 | CS2: 1 | CT2: 0 | CU2: 2 | CV2: 1 | CW2: 1 | CX2: 0 | CY2: 1 | CZ2: 0 | DA2: 0 | DB2: 0 | DC2: 1 | DD2: 0 | DE2: 1 | DF2: 0 | DG2: 0 | DH2: 0 | DI2: 2 | DJ2: 1 | DK2: 2 | DL2: 0 | DM2: 3 | DN2: 0 | DO2: 0 | DP2: 0 | DQ2: 1 | DR2: =YEAR($A2) -> 2015 | DS2: =SUM(N2:Y2) -> 153
A3: =DATE(YEAR(A2),MONTH(A2)+1,DAY(A2)) -> 42036 | B3: 54 | C3: 105 | D3: 73 | E3: 71 | F3: 49 | G3: 51 | H3: 48 | I3: 34 | J3: 31 | K3: 27 | L3: 15 | M3: 23 | N3: 10 | O3: 24 | P3: 22 | Q3: 22 | R3: 14 | S3: 13 | T3: 18 | U3: 14 | V3: 15 | W3: 10 | X3: 12 | Y3: 15 | Z3: 14 | AA3: 10 | AB3: 8 | AC3: 11 | AD3: 8 | AE3: 9 | AF3: 10 | AG3: 11 | AH3: 5 | AI3: 6 | AJ3: 7 | AK3: 8 | AL3: 7 | AM3: 8 | AN3: 5 | AO3: 5 | AP3: 1 | AQ3: 3 | AR3: 5 | AS3: 7 | AT3: 5 | AU3: 3 | AV3: 4 | AW3: 6 | AX3: 7 | AY3: 1 | AZ3: 3 | BA3: 7 | BB3: 4 | BC3: 4 | BD3: 5 | BE3: 3 | BF3: 2 | BG3: 2 | BH3: 4 | BI3: 4 | BJ3: 1 | BK3: 2 | BL3: 1 | BM3: 4 | BN3: 1 | BO3: 5 | BP3: 1 | BQ3: 1 | BR3: 3 | BS3: 5 | BT3: 3 | BU3: 2 | BV3: 1 | BW3: 0 | BX3: 0 | BY3: 1 | BZ3: 2 | CA3: 2 | CB3: 1 | CC3: 1 | CD3: 3 | CE3: 0 | CF3: 1 | CG3: 1 | CH3: 3 | CI3: 0 | CJ3: 0 | CK3: 2 | CL3: 5 | CM3: 0 | CN3: 4 | CO3: 0 | CP3: 1 | CQ3: 0 | CR3: 1 | CS3: 2 | CT3: 0 | CU3: 2 | CV3: 1 | CW3: 1 | CX3: 4 | CY3: 1 | CZ3: 1 | DA3: 0 | DB3: 1 | DC3: 0 | DD3: 0 | DE3: 0 | DF3: 1 | DG3: 1 | DH3: 0 | DI3: 3 | DJ3: 2 | DK3: 2 | DL3: 1 | DM3: 0 | DN3: 2 | DO3: 0 | DP3: 0 | DR3: =YEAR($A3) -> 2015
A4: =DATE(YEAR(A3),MONTH(A3)+1,DAY(A3)) -> 42064 | B4: 48 | C4: 94 | D4: 60 | E4: 61 | F4: 43 | G4: 40 | H4: 35 | I4: 34 | J4: 23 | K4: 23 | L4: 16 | M4: 20 | N4: 35 | O4: 22 | P4: 19 | Q4: 15 | R4: 13 | S4: 11 | T4: 17 | U4: 17 | V4: 16 | W4: 10 | X4: 12 | Y4: 12 | Z4: 8 | AA4: 10 | AB4: 9 | AC4: 9 | AD4: 9 | AE4: 9 | AF4: 9 | AG4: 8 | AH4: 3 | AI4: 8 | AJ4: 7 | AK4: 9 | AL4: 2 | AM4: 7 | AN4: 11 | AO4: 4 | AP4: 6 | AQ4: 4 | AR4: 7 | AS4: 9 | AT4: 5 | AU4: 4 | AV4: 4 | AW4: 3 | AX4: 3 | AY4: 5 | AZ4: 3 | BA4: 2 | BB4: 4 | BC4: 2 | BD4: 1 | BE4: 2 | BF4: 1 | BG4: 5 | BH4: 2 | BI4: 7 | BJ4: 4 | BK4: 2 | BL4: 4 | BM4: 2 | BN4: 4 | BO4: 2 | BP4: 3 | BQ4: 2 | BR4: 2 | BS4: 2 | BT4: 2 | BU4: 5 | BV4: 0 | BW4: 4 | BX4: 1 | BY4: 2 | BZ4: 0 | CA4: 3 | CB4: 0 | CC4: 2 | CD4: 1 | CE4: 0 | CF4: 0 | CG4: 2 | CH4: 1 | CI4: 1 | CJ4: 2 | CK4: 2 | CL4: 2 | CM4: 1 | CN4: 0 | CO4: 1 | CP4: 0 | CQ4: 0 | CR4: 0 | CS4: 1 | CT4: 1 | CU4: 1 | CV4: 2 | CW4: 0 | CX4: 0 | CY4: 2 | CZ4: 0 | DA4: 0 | DB4: 0 | DC4: 3 | DD4: 0 | DE4: 3 | DF4: 3 | DG4: 0 | DH4: 0 | DI4: 0 | DJ4: 0 | DK4: 1 | DL4: 0 | DM4: 0 | DN4: 1 | DO4: 0 | DR4: =YEAR($A4) -> 2015
A5: =DATE(YEAR(A4),MONTH(A4)+1,DAY(A4)) -> 42095 | B5: 68 | C5: 90 | D5: 58 | E5: 63 | F5: 31 | G5: 61 | H5: 35 | I5: 34 | J5: 26 | K5: 21 | L5: 24 | M5: 25 | N5: 23 | O5: 22 | P5: 17 | Q5: 16 | R5: 13 | S5: 16 | T5: 13 | U5: 11 | V5: 15 | W5: 11 | X5: 6 | Y5: 11 | Z5: 13 | AA5: 12 | AB5: 8 | AC5: 4 | AD5: 10 | AE5: 6 | AF5: 9 | AG5: 6 | AH5: 5 | AI5: 3 | AJ5: 10 | AK5: 6 | AL5: 7 | AM5: 4 | AN5: 6 | AO5: 4 | AP5: 5 | AQ5: 7 | AR5: 5 | AS5: 3 | AT5: 3 | AU5: 5 | AV5: 7 | AW5: 4 | AX5: 4 | AY5: 5 | AZ5: 1 | BA5: 5 | BB5: 3 | BC5: 4 | BD5: 3 | BE5: 2 | BF5: 1 | BG5: 2 | BH5: 6 | BI5: 4 | BJ5: 2 | BK5: 2 | BL5: 2 | BM5: 1 | BN5: 3 | BO5: 6 | BP5: 5 | BQ5: 3 | BR5: 3 | BS5: 1 | BT5: 3 | BU5: 3 | BV5: 2 | BW5: 3 | BX5: 2 | BY5: 0 | BZ5: 0 | CA5: 5 | CB5: 3 | CC5: 1 | CD5: 3 | CE5: 1 | CF5: 1 | CG5: 3 | CH5: 3 | CI5: 3 | CJ5: 5 | CK5: 0 | CL5: 0 | CM5: 0 | CN5: 3 | CO5: 4 | CP5: 2 | CQ5: 1 | CR5: 2 | CS5: 3 | CT5: 2 | CU5: 1 | CV5: 2 | CW5: 1 | CX5: 2 | CY5: 1 | CZ5: 2 | DA5: 1 | DB5: 0 | DC5: 0 | DD5: 1 | DE5: 1 | DF5: 2 | DG5: 2 | DH5: 2 | DI5: 1 | DJ5: 0 | DK5: 0 | DL5: 0 | DM5: 0 | DN5: 0 | DR5: =YEAR($A5) -> 2015
A6: =DATE(YEAR(A5),MONTH(A5)+1,DAY(A5)) -> 42125 | B6: 54 | C6: 84 | D6: 68 | E6: 64 | F6: 50 | G6: 45 | H6: 25 | I6: 32 | J6: 30 | K6: 29 | L6: 29 | M6: 26 | N6: 16 | O6: 20 | P6: 18 | Q6: 18 | R6: 7 | S6: 17 | T6: 12 | U6: 17 | V6: 13 | W6: 15 | X6: 9 | Y6: 9 | Z6: 7 | AA6: 6 | AB6: 2 | AC6: 5 | AD6: 9 | AE6: 3 | AF6: 8 | AG6: 7 | AH6: 6 | AI6: 9 | AJ6: 8 | AK6: 6 | AL6: 7 | AM6: 5 | AN6: 2 | AO6: 4 | AP6: 7 | AQ6: 5 | AR6: 7 | AS6: 4 | AT6: 4 | AU6: 4 | AV6: 2 | AW6: 5 | AX6: 2 | AY6: 2 | AZ6: 5 | BA6: 2 | BB6: 5 | BC6: 3 | BD6: 1 | BE6: 1 | BF6: 1 | BG6: 5 | BH6: 4 | BI6: 3 | BJ6: 4 | BK6: 2 | BL6: 0 | BM6: 2 | BN6: 1 | BO6: 2 | BP6: 6 | BQ6: 2 | BR6: 2 | BS6: 0 | BT6: 3 | BU6: 3 | BV6: 2 | BW6: 1 | BX6: 2 | BY6: 2 | BZ6: 1 | CA6: 0 | CB6: 3 | CC6: 3 | CD6: 1 | CE6: 2 | CF6: 4 | CG6: 1 | CH6: 1 | CI6: 1 | CJ6: 0 | CK6: 3 | CL6: 1 | CM6: 2 | CN6: 1 | CO6: 0 | CP6: 3 | CQ6: 0 | CR6: 1 | CS6: 0 | CT6: 0 | CU6: 1 | CV6: 1 | CW6: 0 | CX6: 1 | CY6: 0 | CZ6: 3 | DA6: 0 | DB6: 1 | DC6: 0 | DD6: 4 | DE6: 0 | DF6: 1 | DG6: 3 | DH6: 0 | DI6: 1 | DJ6: 1 | DK6: 1 | DL6: 0 | DM6: 0 | DR6: =YEAR($A6) -> 2015
A7: =DATE(YEAR(A6),MONTH(A6)+1,DAY(A6)) -> 42156 | B7: 47 | C7: 97 | D7: 44 | E7: 55 | F7: 37 | G7: 22 | H7: 36 | I7: 22 | J7: 27 | K7: 20 | L7: 22 | M7: 19 | N7: 11 | O7: 18 | P7: 19 | Q7: 13 | R7: 13 | S7: 14 | T7: 14 | U7: 6 | V7: 10 | W7: 10 | X7: 13 | Y7: 12 | Z7: 8 | AA7: 10 | AB7: 7 | AC7: 4 | AD7: 11 | AE7: 8 | AF7: 7 | AG7: 5 | AH7: 2 | AI7: 3 | AJ7: 1 | AK7: 3 | AL7: 9 | AM7: 0 | AN7: 9 | AO7: 3 | AP7: 9 | AQ7: 2 | AR7: 3 | AS7: 4 | AT7: 3 | AU7: 0 | AV7: 2 | AW7: 2 | AX7: 0 | AY7: 7 | AZ7: 1 | BA7: 3 | BB7: 4 | BC7: 2 | BD7: 3 | BE7: 1 | BF7: 1 | BG7: 2 | BH7: 3 | BI7: 1 | BJ7: 1 | BK7: 3 | BL7: 2 | BM7: 0 | BN7: 0 | BO7: 1 | BP7: 2 | BQ7: 2 | BR7: 5 | BS7: 2 | BT7: 2 | BU7: 3 | BV7: 2 | BW7: 2 | BX7: 1 | BY7: 0 | BZ7: 1 | CA7: 1 | CB7: 3 | CC7: 2 | CD7: 0 | CE7: 2 | CF7: 3 | CG7: 3 | CH7: 1 | CI7: 2 | CJ7: 0 | CK7: 2 | CL7: 0 | CM7: 1 | CN7: 2 | CO7: 1 | CP7: 0 | CQ7: 1 | CR7: 0 | CS7: 4 | CT7: 0 | CU7: 2 | CV7: 0 | CW7: 1 | CX7: 2 | CY7: 0 | CZ7: 1 | DA7: 0 | DB7: 0 | DC7: 0 | DD7: 2 | DE7: 1 | DF7: 1 | DG7: 3 | DH7: 3 | DI7: 1 | DJ7: 1 | DK7: 0 | DL7: 2 | DR7: =YEAR($A7) -> 2015
A8: =DATE(YEAR(A7),MONTH(A7)+1,DAY(A7)) -> 42186 | B8: 28 | C8: 41 | D8: 28 | E8: 41 | F8: 37 | G8: 47 | H8: 22 | I8: 20 | J8: 26 | K8: 20 | L8: 17 | M8: 13 | N8: 18 | O8: 21 | P8: 15 | Q8: 19 | R8: 16 | S8: 12 | T8: 12 | U8: 7 | V8: 7 | W8: 8 | X8: 4 | Y8: 6 | Z8: 2 | AA8: 9 | AB8: 10 | AC8: 11 | AD8: 5 | AE8: 6 | AF8: 6 | AG8: 7 | AH8: 4 | AI8: 4 | AJ8: 9 | AK8: 10 | AL8: 8 | AM8: 3 | AN8: 6 | AO8: 4 | AP8: 2 | AQ8: 5 | AR8: 5 | AS8: 1 | AT8: 1 | AU8: 2 | AV8: 7 | AW8: 5 | AX8: 1 | AY8: 5 | AZ8: 3 | BA8: 2 | BB8: 3 | BC8: 4 | BD8: 2 | BE8: 5 | BF8: 2 | BG8: 4 | BH8: 0 | BI8: 2 | BJ8: 3 | BK8: 5 | BL8: 0 | BM8: 5 | BN8: 2 | BO8: 4 | BP8: 0 | BQ8: 0 | BR8: 1 | BS8: 0 | BT8: 3 | BU8: 0 | BV8: 0 | BW8: 2 | BX8: 5 | BY8: 0 | BZ8: 1 | CA8: 2 | CB8: 3 | CC8: 0 | CD8: 1 | CE8: 1 | CF8: 3 | CG8: 2 | CH8: 1 | CI8: 0 | CJ8: 0 | CK8: 0 | CL8: 1 | CM8: 1 | CN8: 1 | CO8: 4 | CP8: 0 | CQ8: 0 | CR8: 0 | CS8: 2 | CT8: 1 | CU8: 0 | CV8: 1 | CW8: 2 | CX8: 0 | CY8: 1 | CZ8: 1 | DA8: 0 | DB8: 0 | DC8: 1 | DD8: 1 | DE8: 1 | DF8: 0 | DG8: 3 | DH8: 1 | DI8: 0 | DJ8: 1 | DK8: 0 | DR8: =YEAR($A8) -> 2015
A9: =DATE(YEAR(A8),MONTH(A8)+1,DAY(A8)) -> 42217 | B9: 33 | C9: 57 | D9: 39 | E9: 48 | F9: 35 | G9: 30 | H9: 29 | I9: 28 | J9: 28 | K9: 14 | L9: 18 | M9: 14 | N9: 11 | O9: 22 | P9: 20 | Q9: 15 | R9: 8 | S9: 12 | T9: 7 | U9: 5 | V9: 4 | W9: 6 | X9: 8 | Y9: 5 | Z9: 3 | AA9: 7 | AB9: 4 | AC9: 5 | AD9: 11 | AE9: 6 | AF9: 5 | AG9: 8 | AH9: 2 | AI9: 3 | AJ9: 3 | AK9: 8 | AL9: 1 | AM9: 4 | AN9: 2 | AO9: 4 | AP9: 1 | AQ9: 1 | AR9: 5 | AS9: 1 | AT9: 9 | AU9: 2 | AV9: 5 | AW9: 5 | AX9: 1 | AY9: 4 | AZ9: 0 | BA9: 2 | BB9: 4 | BC9: 1 | BD9: 2 | BE9: 6 | BF9: 3 | BG9: 1 | BH9: 1 | BI9: 1 | BJ9: 2 | BK9: 3 | BL9: 2 | BM9: 1 | BN9: 3 | BO9: 3 | BP9: 1 | BQ9: 2 | BR9: 0 | BS9: 1 | BT9: 0 | BU9: 5 | BV9: 1 | BW9: 1 | BX9: 0 | BY9: 2 | BZ9: 1 | CA9: 0 | CB9: 1 | CC9: 1 | CD9: 1 | CE9: 2 | CF9: 2 | CG9: 3 | CH9: 1 | CI9: 0 | CJ9: 1 | CK9: 1 | CL9: 0 | CM9: 1 | CN9: 0 | CO9: 1 | CP9: 2 | CQ9: 1 | CR9: 0 | CS9: 1 | CT9: 1 | CU9: 1 | CV9: 1 | CW9: 1 | CX9: 0 | CY9: 0 | CZ9: 0 | DA9: 1 | DB9: 1 | DC9: 2 | DD9: 2 | DE9: 1 | DF9: 3 | DG9: 0 | DH9: 0 | DI9: 0 | DJ9: 0 | DR9: =YEAR($A9) -> 2015
A10: =DATE(YEAR(A9),MONTH(A9)+1,DAY(A9)) -> 42248 | B10: 40 | C10: 73 | D10: 37 | E10: 45 | F10: 38 | G10: 39 | H10: 20 | I10: 25 | J10: 31 | K10: 20 | L10: 13 | M10: 13 | N10: 17 | O10: 12 | P10: 12 | Q10: 11 | R10: 17 | S10: 9 | T10: 7 | U10: 9 | V10: 8 | W10: 6 | X10: 5 | Y10: 10 | Z10: 9 | AA10: 7 | AB10: 6 | AC10: 7 | AD10: 4 | AE10: 3 | AF10: 8 | AG10: 5 | AH10: 6 | AI10: 6 | AJ10: 3 | AK10: 3 | AL10: 3 | AM10: 4 | AN10: 3 | AO10: 1 | AP10: 6 | AQ10: 5 | AR10: 3 | AS10: 5 | AT10: 3 | AU10: 3 | AV10: 5 | AW10: 2 | AX10: 5 | AY10: 0 | AZ10: 3 | BA10: 1 | BB10: 4 | BC10: 1 | BD10: 1 | BE10: 1 | BF10: 3 | BG10: 4 | BH10: 4 | BI10: 1 | BJ10: 1 | BK10: 0 | BL10: 2 | BM10: 1 | BN10: 1 | BO10: 1 | BP10: 5 | BQ10: 2 | BR10: 2 | BS10: 1 | BT10: 0 | BU10: 0 | BV10: 2 | BW10: 1 | BX10: 0 | BY10: 3 | BZ10: 2 | CA10: 2 | CB10: 2 | CC10: 2 | CD10: 1 | CE10: 2 | CF10: 0 | CG10: 0 | CH10: 1 | CI10: 1 | CJ10: 1 | CK10: 1 | CL10: 2 | CM10: 0 | CN10: 2 | CO10: 1 | CP10: 2 | CQ10: 0 | CR10: 1 | CS10: 2 | CT10: 2 | CU10: 1 | CV10: 0 | CW10: 0 | CX10: 1 | CY10: 0 | CZ10: 0 | DA10: 1 | DB10: 2 | DC10: 0 | DD10: 1 | DE10: 0 | DF10: 1 | DG10: 1 | DH10: 0 | DI10: 1 | DR10: =YEAR($A10) -> 2015
A11: =DATE(YEAR(A10),MONTH(A10)+1,DAY(A10)) -> 42278 | B11: 60 | C11: 98 | D11: 50 | E11: 69 | F11: 55 | G11: 44 | H11: 40 | I11: 33 | J11: 33 | K11: 30 | L11: 23 | M11: 24 | N11: 28 | O11: 20 | P11: 15 | Q11: 22 | R11: 16 | S11: 12 | T11: 10 | U11: 9 | V11: 13 | W11: 13 | X11: 5 | Y11: 7 | Z11: 7 | AA11: 5 | AB11: 10 | AC11: 13 | AD11: 7 | AE11: 9 | AF11: 4 | AG11: 5 | AH11: 7 | AI11: 7 | AJ11: 8 | AK11: 2 | AL11: 5 | AM11: 6 | AN11: 6 | AO11: 6 | AP11: 1 | AQ11: 2 | AR11: 5 | AS11: 2 | AT11: 1 | AU11: 4 | AV11: 1 | AW11: 3 | AX11: 7 | AY11: 6 | AZ11: 4 | BA11: 1 | BB11: 4 | BC11: 6 | BD11: 2 | BE11: 4 | BF11: 4 | BG11: 4 | BH11: 0 | BI11: 3 | BJ11: 2 | BK11: 3 | BL11: 5 | BM11: 2 | BN11: 2 | BO11: 2 | BP11: 3 | BQ11: 0 | BR11: 2 | BS11: 2 | BT11: 3 | BU11: 2 | BV11: 1 | BW11: 5 | BX11: 2 | BY11: 2 | BZ11: 2 | CA11: 0 | CB11: 1 | CC11: 3 | CD11: 1 | CE11: 1 | CF11: 0 | CG11: 1 | CH11: 1 | CI11: 0 | CJ11: 0 | CK11: 1 | CL11: 1 | CM11: 0 | CN11: 1 | CO11: 0 | CP11: 3 | CQ11: 1 | CR11: 1 | CS11: 1 | CT11: 0 | CU11: 0 | CV11: 0 | CW11: 2 | CX11: 0 | CY11: 1 | CZ11: 2 | DA11: 1 | DB11: 1 | DC11: 1 | DD11: 0 | DE11: 1 | DF11: 3 | DG11: 1 | DH11: 0 | DR11: =YEAR($A11) -> 2015
A12: =DATE(YEAR(A11),MONTH(A11)+1,DAY(A11)) -> 42309 | B12: 45 | C12: 107 | D12: 62 | E12: 61 | F12: 44 | G12: 33 | H12: 36 | I12: 31 | J12: 29 | K12: 10 | L12: 9 | M12: 25 | N12: 14 | O12: 20 | P12: 19 | Q12: 21 | R12: 15 | S12: 11 | T12: 14 | U12: 11 | V12: 5 | W12: 12 | X12: 12 | Y12: 8 | Z12: 6 | AA12: 11 | AB12: 4 | AC12: 13 | AD12: 7 | AE12: 4 | AF12: 2 | AG12: 6 | AH12: 4 | AI12: 5 | AJ12: 6 | AK12: 2 | AL12: 9 | AM12: 6 | AN12: 7 | AO12: 2 | AP12: 1 | AQ12: 4 | AR12: 4 | AS12: 6 | AT12: 2 | AU12: 7 | AV12: 5 | AW12: 7 | AX12: 3 | AY12: 1 | AZ12: 4 | BA12: 2 | BB12: 4 | BC12: 1 | BD12: 2 | BE12: 1 | BF12: 3 | BG12: 5 | BH12: 1 | BI12: 2 | BJ12: 3 | BK12: 2 | BL12: 1 | BM12: 3 | BN12: 0 | BO12: 2 | BP12: 3 | BQ12: 3 | BR12: 1 | BS12: 1 | BT12: 0 | BU12: 2 | BV12: 2 | BW12: 1 | BX12: 0 | BY12: 0 | BZ12: 2 | CA12: 1 | CB12: 1 | CC12: 3 | CD12: 3 | CE12: 1 | CF12: 1 | CG12: 1 | CH12: 2 | CI12: 1 | CJ12: 0 | CK12: 2 | CL12: 2 | CM12: 3 | CN12: 0 | CO12: 1 | CP12: 0 | CQ12: 0 | CR12: 1 | CS12: 2 | CT12: 2 | CU12: 1 | CV12: 2 | CW12: 2 | CX12: 1 | CY12: 0 | CZ12: 2 | DA12: 0 | DB12: 1 | DC12: 2 | DD12: 2 | DE12: 0 | DF12: 0 | DG12: 0 | DR12: =YEAR($A12) -> 2015
A13: =DATE(YEAR(A12),MONTH(A12)+1,DAY(A12)) -> 42339 | B13: 60 | C13: 78 | D13: 57 | E13: 55 | F13: 56 | G13: 32 | H13: 27 | I13: 30 | J13: 22 | K13: 28 | L13: 22 | M13: 20 | N13: 29 | O13: 20 | P13: 13 | Q13: 13 | R13: 14 | S13: 6 | T13: 5 | U13: 8 | V13: 8 | W13: 9 | X13: 7 | Y13: 8 | Z13: 6 | AA13: 7 | AB13: 4 | AC13: 4 | AD13: 10 | AE13: 3 | AF13: 9 | AG13: 3 | AH13: 7 | AI13: 8 | AJ13: 6 | AK13: 2 | AL13: 3 | AM13: 6 | AN13: 6 | AO13: 3 | AP13: 1 | AQ13: 3 | AR13: 3 | AS13: 2 | AT13: 2 | AU13: 5 | AV13: 2 | AW13: 6 | AX13: 4 | AY13: 2 | AZ13: 4 | BA13: 2 | BB13: 7 | BC13: 1 | BD13: 0 | BE13: 5 | BF13: 3 | BG13: 1 | BH13: 0 | BI13: 1 | BJ13: 0 | BK13: 0 | BL13: 5 | BM13: 0 | BN13: 4 | BO13: 0 | BP13: 2 | BQ13: 0 | BR13: 0 | BS13: 3 | BT13: 3 | BU13: 1 | BV13: 1 | BW13: 0 | BX13: 2 | BY13: 5 | BZ13: 1 | CA13: 0 | CB13: 3 | CC13: 1 | CD13: 0 | CE13: 1 | CF13: 1 | CG13: 2 | CH13: 0 | CI13: 2 | CJ13: 2 | CK13: 1 | CL13: 0 | CM13: 0 | CN13: 2 | CO13: 0 | CP13: 0 | CQ13: 2 | CR13: 2 | CS13: 0 | CT13: 2 | CU13: 2 | CV13: 0 | CW13: 0 | CX13: 5 | CY13: 0 | CZ13: 0 | DA13: 0 | DB13: 1 | DC13: 0 | DD13: 0 | DE13: 2 | DF13: 0 | DR13: =YEAR($A13) -> 2015
A14: =DATE(YEAR(A13),MONTH(A13)+1,DAY(A13)) -> 42370 | B14: 55 | C14: 67 | D14: 81 | E14: 58 | F14: 53 | G14: 34 | H14: 41 | I14: 27 | J14: 27 | K14: 16 | L14: 22 | M14: 24 | N14: 15 | O14: 12 | P14: 12 | Q14: 7 | R14: 8 | S14: 5 | T14: 12 | U14: 11 | V14: 13 | W14: 10 | X14: 8 | Y14: 8 | Z14: 6 | AA14: 6 | AB14: 5 | AC14: 7 | AD14: 11 | AE14: 8 | AF14: 9 | AG14: 7 | AH14: 5 | AI14: 4 | AJ14: 4 | AK14: 3 | AL14: 10 | AM14: 3 | AN14: 4 | AO14: 5 | AP14: 3 | AQ14: 3 | AR14: 2 | AS14: 3 | AT14: 3 | AU14: 1 | AV14: 4 | AW14: 4 | AX14: 5 | AY14: 2 | AZ14: 8 | BA14: 4 | BB14: 3 | BC14: 5 | BD14: 4 | BE14: 3 | BF14: 1 | BG14: 1 | BH14: 5 | BI14: 2 | BJ14: 0 | BK14: 2 | BL14: 2 | BM14: 0 | BN14: 2 | BO14: 1 | BP14: 0 | BQ14: 1 | BR14: 2 | BS14: 0 | BT14: 2 | BU14: 2 | BV14: 1 | BW14: 1 | BX14: 1 | BY14: 5 | BZ14: 1 | CA14: 0 | CB14: 2 | CC14: 0 | CD14: 1 | CE14: 1 | CF14: 1 | CG14: 1 | CH14: 1 | CI14: 0 | CJ14: 1 | CK14: 1 | CL14: 0 | CM14: 3 | CN14: 3 | CO14: 1 | CP14: 1 | CQ14: 1 | CR14: 1 | CS14: 2 | CT14: 3 | CU14: 2 | CV14: 0 | CW14: 0 | CX14: 1 | CY14: 1 | CZ14: 0 | DA14: 1 | DB14: 1 | DC14: 0 | DD14: 1 | DE14: 1 | DR14: =YEAR($A14) -> 2016
A15: =DATE(YEAR(A14),MONTH(A14)+1,DAY(A14)) -> 42401 | B15: 48 | C15: 85 | D15: 75 | E15: 76 | F15: 53 | G15: 57 | H15: 28 | I15: 36 | J15: 29 | K15: 25 | L15: 32 | M15: 18 | N15: 21 | O15: 20 | P15: 10 | Q15: 16 | R15: 8 | S15: 10 | T15: 13 | U15: 12 | V15: 13 | W15: 11 | X15: 11 | Y15: 9 | Z15: 9 | AA15: 4 | AB15: 10 | AC15: 11 | AD15: 6 | AE15: 5 | AF15: 8 | AG15: 11 | AH15: 6 | AI15: 2 | AJ15: 6 | AK15: 5 | AL15: 6 | AM15: 7 | AN15: 2 | AO15: 2 | AP15: 4 | AQ15: 7 | AR15: 1 | AS15: 6 | AT15: 3 | AU15: 4 | AV15: 4 | AW15: 3 | AX15: 3 | AY15: 4 | AZ15: 3 | BA15: 2 | BB15: 5 | BC15: 1 | BD15: 4 | BE15: 0 | BF15: 5 | BG15: 4 | BH15: 4 | BI15: 4 | BJ15: 1 | BK15: 1 | BL15: 3 | BM15: 1 | BN15: 2 | BO15: 5 | BP15: 0 | BQ15: 2 | BR15: 4 | BS15: 3 | BT15: 1 | BU15: 3 | BV15: 0 | BW15: 2 | BX15: 1 | BY15: 3 | BZ15: 4 | CA15: 1 | CB15: 2 | CC15: 1 | CD15: 1 | CE15: 3 | CF15: 1 | CG15: 0 | CH15: 0 | CI15: 0 | CJ15: 2 | CK15: 0 | CL15: 2 | CM15: 0 | CN15: 0 | CO15: 1 | CP15: 1 | CQ15: 1 | CR15: 0 | CS15: 2 | CT15: 3 | CU15: 1 | CV15: 0 | CW15: 1 | CX15: 1 | CY15: 3 | CZ15: 0 | DA15: 0 | DB15: 0 | DC15: 0 | DD15: 0 | DR15: =YEAR($A15) -> 2016
A16: =DATE(YEAR(A15),MONTH(A15)+1,DAY(A15)) -> 42430 | B16: 61 | C16: 96 | D16: 63 | E16: 64 | F16: 49 | G16: 50 | H16: 44 | I16: 21 | J16: 24 | K16: 31 | L16: 27 | M16: 17 | N16: 22 | O16: 20 | P16: 16 | Q16: 14 | R16: 14 | S16: 12 | T16: 8 | U16: 15 | V16: 10 | W16: 9 | X16: 16 | Y16: 13 | Z16: 11 | AA16: 7 | AB16: 2 | AC16: 9 | AD16: 8 | AE16: 8 | AF16: 5 | AG16: 10 | AH16: 5 | AI16: 8 | AJ16: 4 | AK16: 3 | AL16: 11 | AM16: 4 | AN16: 5 | AO16: 7 | AP16: 8 | AQ16: 1 | AR16: 1 | AS16: 3 | AT16: 1 | AU16: 4 | AV16: 2 | AW16: 3 | AX16: 2 | AY16: 2 | AZ16: 3 | BA16: 5 | BB16: 2 | BC16: 2 | BD16: 4 | BE16: 4 | BF16: 0 | BG16: 2 | BH16: 2 | BI16: 3 | BJ16: 1 | BK16: 1 | BL16: 1 | BM16: 1 | BN16: 1 | BO16: 2 | BP16: 2 | BQ16: 3 | BR16: 2 | BS16: 3 | BT16: 0 | BU16: 4 | BV16: 1 | BW16: 2 | BX16: 3 | BY16: 0 | BZ16: 2 | CA16: 0 | CB16: 0 | CC16: 1 | CD16: 2 | CE16: 1 | CF16: 1 | CG16: 0 | CH16: 0 | CI16: 1 | CJ16: 3 | CK16: 1 | CL16: 1 | CM16: 0 | CN16: 1 | CO16: 2 | CP16: 3 | CQ16: 0 | CR16: 0 | CS16: 3 | CT16: 0 | CU16: 1 | CV16: 3 | CW16: 0 | CX16: 1 | CY16: 0 | CZ16: 2 | DA16: 0 | DB16: 0 | DC16: 0 | DR16: =YEAR($A16) -> 2016
A17: =DATE(YEAR(A16),MONTH(A16)+1,DAY(A16)) -> 42461 | B17: 73 | C17: 106 | D17: 68 | E17: 78 | F17: 49 | G17: 37 | H17: 44 | I17: 41 | J17: 24 | K17: 26 | L17: 26 | M17: 29 | N17: 19 | O17: 19 | P17: 7 | Q17: 13 | R17: 13 | S17: 17 | T17: 15 | U17: 12 | V17: 11 | W17: 7 | X17: 7 | Y17: 15 | Z17: 13 | AA17: 8 | AB17: 7 | AC17: 5 | AD17: 6 | AE17: 7 | AF17: 10 | AG17: 6 | AH17: 5 | AI17: 5 | AJ17: 1 | AK17: 5 | AL17: 4 | AM17: 7 | AN17: 7 | AO17: 3 | AP17: 4 | AQ17: 6 | AR17: 5 | AS17: 6 | AT17: 0 | AU17: 5 | AV17: 6 | AW17: 6 | AX17: 7 | AY17: 4 | AZ17: 2 | BA17: 5 | BB17: 4 | BC17: 2 | BD17: 2 | BE17: 4 | BF17: 1 | BG17: 0 | BH17: 1 | BI17: 4 | BJ17: 2 | BK17: 3 | BL17: 3 | BM17: 2 | BN17: 5 | BO17: 0 | BP17: 2 | BQ17: 2 | BR17: 2 | BS17: 3 | BT17: 1 | BU17: 5 | BV17: 5 | BW17: 3 | BX17: 0 | BY17: 2 | BZ17: 1 | CA17: 1 | CB17: 2 | CC17: 2 | CD17: 1 | CE17: 0 | CF17: 3 | CG17: 3 | CH17: 1 | CI17: 2 | CJ17: 2 | CK17: 5 | CL17: 3 | CM17: 0 | CN17: 1 | CO17: 0 | CP17: 1 | CQ17: 0 | CR17: 2 | CS17: 0 | CT17: 0 | CU17: 1 | CV17: 2 | CW17: 3 | CX17: 3 | CY17: 2 | CZ17: 0 | DA17: 0 | DB17: 0 | DR17: =YEAR($A17) -> 2016
A18: =DATE(YEAR(A17),MONTH(A17)+1,DAY(A17)) -> 42491 | B18: 55 | C18: 64 | D18: 44 | E18: 46 | F18: 33 | G18: 36 | H18: 40 | I18: 24 | J18: 23 | K18: 23 | L18: 19 | M18: 21 | N18: 12 | O18: 11 | P18: 13 | Q18: 9 | R18: 8 | S18: 8 | T18: 15 | U18: 9 | V18: 7 | W18: 6 | X18: 13 | Y18: 5 | Z18: 6 | AA18: 7 | AB18: 6 | AC18: 4 | AD18: 2 | AE18: 2 | AF18: 5 | AG18: 3 | AH18: 6 | AI18: 2 | AJ18: 4 | AK18: 4 | AL18: 7 | AM18: 9 | AN18: 7 | AO18: 4 | AP18: 6 | AQ18: 2 | AR18: 1 | AS18: 2 | AT18: 5 | AU18: 2 | AV18: 4 | AW18: 4 | AX18: 2 | AY18: 7 | AZ18: 2 | BA18: 3 | BB18: 2 | BC18: 1 | BD18: 4 | BE18: 2 | BF18: 2 | BG18: 2 | BH18: 2 | BI18: 3 | BJ18: 1 | BK18: 0 | BL18: 4 | BM18: 3 | BN18: 2 | BO18: 1 | BP18: 0 | BQ18: 4 | BR18: 2 | BS18: 0 | BT18: 2 | BU18: 3 | BV18: 2 | BW18: 3 | BX18: 1 | BY18: 1 | BZ18: 0 | CA18: 2 | CB18: 3 | CC18: 0 | CD18: 0 | CE18: 1 | CF18: 0 | CG18: 3 | CH18: 1 | CI18: 3 | CJ18: 1 | CK18: 1 | CL18: 1 | CM18: 0 | CN18: 2 | CO18: 0 | CP18: 0 | CQ18: 0 | CR18: 0 | CS18: 0 | CT18: 0 | CU18: 1 | CV18: 2 | CW18: 3 | CX18: 0 | CY18: 0 | CZ18: 0 | DA18: 0 | DR18: =YEAR($A18) -> 2016
A19: =DATE(YEAR(A18),MONTH(A18)+1,DAY(A18)) -> 42522 | B19: 49 | C19: 103 | D19: 48 | E19: 54 | F19: 31 | G19: 18 | H19: 30 | I19: 22 | J19: 16 | K19: 20 | L19: 13 | M19: 13 | N19: 10 | O19: 18 | P19: 6 | Q19: 7 | R19: 12 | S19: 10 | T19: 7 | U19: 3 | V19: 6 | W19: 7 | X19: 4 | Y19: 3 | Z19: 2 | AA19: 6 | AB19: 7 | AC19: 8 | AD19: 3 | AE19: 3 | AF19: 4 | AG19: 2 | AH19: 1 | AI19: 6 | AJ19: 4 | AK19: 5 | AL19: 3 | AM19: 2 | AN19: 1 | AO19: 6 | AP19: 4 | AQ19: 5 | AR19: 4 | AS19: 2 | AT19: 2 | AU19: 4 | AV19: 1 | AW19: 0 | AX19: 0 | AY19: 2 | AZ19: 2 | BA19: 0 | BB19: 4 | BC19: 6 | BD19: 3 | BE19: 2 | BF19: 2 | BG19: 1 | BH19: 5 | BI19: 2 | BJ19: 2 | BK19: 0 | BL19: 0 | BM19: 1 | BN19: 0 | BO19: 2 | BP19: 1 | BQ19: 2 | BR19: 2 | BS19: 4 | BT19: 2 | BU19: 2 | BV19: 1 | BW19: 0 | BX19: 4 | BY19: 1 | BZ19: 1 | CA19: 2 | CB19: 2 | CC19: 0 | CD19: 1 | CE19: 3 | CF19: 0 | CG19: 2 | CH19: 2 | CI19: 0 | CJ19: 2 | CK19: 1 | CL19: 0 | CM19: 0 | CN19: 1 | CO19: 1 | CP19: 0 | CQ19: 0 | CR19: 0 | CS19: 0 | CT19: 2 | CU19: 0 | CV19: 0 | CW19: 2 | CX19: 0 | CY19: 0 | CZ19: 1 | DR19: =YEAR($A19) -> 2016
A20: =DATE(YEAR(A19),MONTH(A19)+1,DAY(A19)) -> 42552 | B20: 60 | C20: 85 | D20: 58 | E20: 52 | F20: 32 | G20: 38 | H20: 33 | I20: 34 | J20: 13 | K20: 21 | L20: 20 | M20: 20 | N20: 7 | O20: 13 | P20: 15 | Q20: 11 | R20: 12 | S20: 13 | T20: 9 | U20: 8 | V20: 6 | W20: 8 | X20: 4 | Y20: 5 | Z20: 8 | AA20: 6 | AB20: 8 | AC20: 2 | AD20: 5 | AE20: 9 | AF20: 6 | AG20: 2 | AH20: 7 | AI20: 1 | AJ20: 4 | AK20: 9 | AL20: 5 | AM20: 3 | AN20: 2 | AO20: 6 | AP20: 2 | AQ20: 4 | AR20: 2 | AS20: 0 | AT20: 5 | AU20: 4 | AV20: 2 | AW20: 3 | AX20: 2 | AY20: 3 | AZ20: 2 | BA20: 3 | BB20: 3 | BC20: 3 | BD20: 2 | BE20: 1 | BF20: 1 | BG20: 1 | BH20: 2 | BI20: 0 | BJ20: 1 | BK20: 2 | BL20: 0 | BM20: 1 | BN20: 1 | BO20: 0 | BP20: 1 | BQ20: 2 | BR20: 2 | BS20: 0 | BT20: 5 | BU20: 4 | BV20: 2 | BW20: 0 | BX20: 1 | BY20: 1 | BZ20: 1 | CA20: 2 | CB20: 1 | CC20: 0 | CD20: 1 | CE20: 2 | CF20: 2 | CG20: 0 | CH20: 1 | CI20: 1 | CJ20: 1 | CK20: 1 | CL20: 0 | CM20: 3 | CN20: 1 | CO20: 0 | CP20: 2 | CQ20: 0 | CR20: 0 | CS20: 0 | CT20: 2 | CU20: 1 | CV20: 2 | CW20: 1 | CX20: 0 | CY20: 0 | DR20: =YEAR($A20) -> 2016
A21: =DATE(YEAR(A20),MONTH(A20)+1,DAY(A20)) -> 42583 | B21: 35 | C21: 58 | D21: 38 | E21: 35 | F21: 29 | G21: 35 | H21: 24 | I21: 18 | J21: 17 | K21: 16 | L21: 6 | M21: 11 | N21: 12 | O21: 5 | P21: 4 | Q21: 8 | R21: 2 | S21: 8 | T21: 9 | U21: 8 | V21: 2 | W21: 4 | X21: 6 | Y21: 4 | Z21: 6 | AA21: 5 | AB21: 8 | AC21: 3 | AD21: 6 | AE21: 2 | AF21: 3 | AG21: 4 | AH21: 1 | AI21: 3 | AJ21: 5 | AK21: 7 | AL21: 2 | AM21: 3 | AN21: 3 | AO21: 1 | AP21: 3 | AQ21: 1 | AR21: 0 | AS21: 2 | AT21: 1 | AU21: 2 | AV21: 1 | AW21: 2 | AX21: 3 | AY21: 2 | AZ21: 2 | BA21: 2 | BB21: 1 | BC21: 1 | BD21: 2 | BE21: 1 | BF21: 1 | BG21: 0 | BH21: 2 | BI21: 1 | BJ21: 1 | BK21: 2 | BL21: 0 | BM21: 0 | BN21: 1 | BO21: 2 | BP21: 0 | BQ21: 1 | BR21: 4 | BS21: 3 | BT21: 1 | BU21: 3 | BV21: 2 | BW21: 0 | BX21: 0 | BY21: 1 | BZ21: 0 | CA21: 0 | CB21: 0 | CC21: 0 | CD21: 0 | CE21: 0 | CF21: 2 | CG21: 0 | CH21: 0 | CI21: 0 | CJ21: 0 | CK21: 0 | CL21: 0 | CM21: 0 | CN21: 1 | CO21: 0 | CP21: 0 | CQ21: 1 | CR21: 0 | CS21: 1 | CT21: 0 | CU21: 1 | CV21: 0 | CW21: 0 | CX21: 0 | DR21: =YEAR($A21) -> 2016
A22: =DATE(YEAR(A21),MONTH(A21)+1,DAY(A21)) -> 42614 | B22: 25 | C22: 44 | D22: 26 | E22: 20 | F22: 22 | G22: 13 | H22: 16 | I22: 8 | J22: 13 | K22: 7 | L22: 10 | M22: 5 | N22: 6 | O22: 7 | P22: 10 | Q22: 7 | R22: 4 | S22: 6 | T22: 5 | U22: 7 | V22: 3 | W22: 4 | X22: 5 | Y22: 1 | Z22: 3 | AA22: 2 | AB22: 2 | AC22: 3 | AD22: 2 | AE22: 3 | AF22: 3 | AG22: 3 | AH22: 2 | AI22: 6 | AJ22: 2 | AK22: 4 | AL22: 1 | AM22: 2 | AN22: 3 | AO22: 0 | AP22: 1 | AQ22: 1 | AR22: 3 | AS22: 1 | AT22: 0 | AU22: 0 | AV22: 1 | AW22: 0 | AX22: 2 | AY22: 3 | AZ22: 1 | BA22: 0 | BB22: 4 | BC22: 0 | BD22: 1 | BE22: 3 | BF22: 1 | BG22: 3 | BH22: 2 | BI22: 0 | BJ22: 1 | BK22: 0 | BL22: 0 | BM22: 0 | BN22: 1 | BO22: 2 | BP22: 0 | BQ22: 0 | BR22: 1 | BS22: 1 | BT22: 1 | BU22: 2 | BV22: 1 | BW22: 0 | BX22: 0 | BY22: 0 | BZ22: 0 | CA22: 1 | CB22: 0 | CC22: 0 | CD22: 0 | CE22: 1 | CF22: 1 | CG22: 0 | CH22: 0 | CI22: 0 | CJ22: 1 | CK22: 0 | CL22: 1 | CM22: 0 | CN22: 0 | CO22: 1 | CP22: 0 | CQ22: 0 | CR22: 0 | CS22: 0 | CT22: 1 | CU22: 0 | CV22: 0 | CW22: 0 | DR22: =YEAR($A22) -> 2016
A23: =DATE(YEAR(A22),MONTH(A22)+1,DAY(A22)) -> 42644 | B23: 39 | C23: 75 | D23: 44 | E23: 39 | F23: 22 | G23: 23 | H23: 20 | I23: 13 | J23: 6 | K23: 14 | L23: 11 | M23: 9 | N23: 13 | O23: 11 | P23: 12 | Q23: 5 | R23: 5 | S23: 6 | T23: 6 | U23: 6 | V23: 4 | W23: 8 | X23: 8 | Y23: 6 | Z23: 4 | AA23: 2 | AB23: 6 | AC23: 6 | AD23: 3 | AE23: 5 | AF23: 4 | AG23: 5 | AH23: 3 | AI23: 5 | AJ23: 4 | AK23: 2 | AL23: 5 | AM23: 1 | AN23: 1 | AO23: 2 | AP23: 2 | AQ23: 3 | AR23: 1 | AS23: 4 | AT23: 5 | AU23: 1 | AV23: 1 | AW23: 4 | AX23: 5 | AY23: 4 | AZ23: 1 | BA23: 1 | BB23: 1 | BC23: 1 | BD23: 1 | BE23: 2 | BF23: 0 | BG23: 2 | BH23: 0 | BI23: 1 | BJ23: 3 | BK23: 2 | BL23: 1 | BM23: 1 | BN23: 3 | BO23: 2 | BP23: 1 | BQ23: 1 | BR23: 1 | BS23: 0 | BT23: 3 | BU23: 2 | BV23: 2 | BW23: 2 | BX23: 2 | BY23: 1 | BZ23: 1 | CA23: 0 | CB23: 1 | CC23: 2 | CD23: 1 | CE23: 2 | CF23: 0 | CG23: 1 | CH23: 2 | CI23: 0 | CJ23: 0 | CK23: 0 | CL23: 0 | CM23: 0 | CN23: 1 | CO23: 0 | CP23: 3 | CQ23: 0 | CR23: 1 | CS23: 1 | CT23: 0 | CU23: 0 | CV23: 1 | DR23: =YEAR($A23) -> 2016
A24: =DATE(YEAR(A23),MONTH(A23)+1,DAY(A23)) -> 42675 | B24: 38 | C24: 45 | D24: 41 | E24: 30 | F24: 25 | G24: 21 | H24: 16 | I24: 8 | J24: 14 | K24: 11 | L24: 13 | M24: 9 | N24: 9 | O24: 15 | P24: 7 | Q24: 9 | R24: 11 | S24: 11 | T24: 7 | U24: 6 | V24: 4 | W24: 5 | X24: 9 | Y24: 8 | Z24: 3 | AA24: 3 | AB24: 4 | AC24: 2 | AD24: 3 | AE24: 5 | AF24: 3 | AG24: 3 | AH24: 4 | AI24: 0 | AJ24: 4 | AK24: 2 | AL24: 2 | AM24: 1 | AN24: 2 | AO24: 2 | AP24: 3 | AQ24: 2 | AR24: 1 | AS24: 1 | AT24: 4 | AU24: 2 | AV24: 3 | AW24: 3 | AX24: 2 | AY24: 0 | AZ24: 2 | BA24: 0 | BB24: 1 | BC24: 2 | BD24: 2 | BE24: 1 | BF24: 0 | BG24: 1 | BH24: 1 | BI24: 2 | BJ24: 3 | BK24: 0 | BL24: 2 | BM24: 1 | BN24: 1 | BO24: 1 | BP24: 0 | BQ24: 1 | BR24: 3 | BS24: 0 | BT24: 2 | BU24: 1 | BV24: 1 | BW24: 0 | BX24: 0 | BY24: 3 | BZ24: 0 | CA24: 1 | CB24: 0 | CC24: 1 | CD24: 3 | CE24: 1 | CF24: 0 | CG24: 0 | CH24: 0 | CI24: 1 | CJ24: 0 | CK24: 2 | CL24: 2 | CM24: 1 | CN24: 1 | CO24: 0 | CP24: 1 | CQ24: 1 | CR24: 0 | CS24: 3 | CT24: 1 | CU24: 0 | DR24: =YEAR($A24) -> 2016
A25: =DATE(YEAR(A24),MONTH(A24)+1,DAY(A24)) -> 42705 | B25: 31 | C25: 62 | D25: 38 | E25: 28 | F25: 20 | G25: 17 | H25: 16 | I25: 16 | J25: 22 | K25: 9 | L25: 15 | M25: 13 | N25: 16 | O25: 8 | P25: 12 | Q25: 5 | R25: 8 | S25: 8 | T25: 5 | U25: 6 | V25: 10 | W25: 8 | X25: 4 | Y25: 5 | Z25: 7 | AA25: 5 | AB25: 3 | AC25: 3 | AD25: 3 | AE25: 6 | AF25: 2 | AG25: 5 | AH25: 1 | AI25: 4 | AJ25: 3 | AK25: 2 | AL25: 3 | AM25: 2 | AN25: 2 | AO25: 1 | AP25: 4 | AQ25: 3 | AR25: 0 | AS25: 1 | AT25: 1 | AU25: 1 | AV25: 1 | AW25: 9 | AX25: 2 | AY25: 1 | AZ25: 1 | BA25: 2 | BB25: 0 | BC25: 1 | BD25: 3 | BE25: 0 | BF25: 2 | BG25: 0 | BH25: 2 | BI25: 3 | BJ25: 2 | BK25: 1 | BL25: 3 | BM25: 2 | BN25: 1 | BO25: 1 | BP25: 1 | BQ25: 4 | BR25: 0 | BS25: 0 | BT25: 6 | BU25: 2 | BV25: 1 | BW25: 1 | BX25: 2 | BY25: 2 | BZ25: 2 | CA25: 1 | CB25: 1 | CC25: 2 | CD25: 0 | CE25: 1 | CF25: 1 | CG25: 1 | CH25: 0 | CI25: 1 | CJ25: 2 | CK25: 0 | CL25: 0 | CM25: 0 | CN25: 1 | CO25: 1 | CP25: 0 | CQ25: 0 | CR25: 1 | CS25: 2 | CT25: 0 | DR25: =YEAR($A25) -> 2016
A26: =DATE(YEAR(A25),MONTH(A25)+1,DAY(A25)) -> 42736 | B26: 44 | C26: 66 | D26: 40 | E26: 41 | F26: 30 | G26: 23 | H26: 25 | I26: 18 | J26: 17 | K26: 21 | L26: 18 | M26: 10 | N26: 11 | O26: 15 | P26: 16 | Q26: 11 | R26: 10 | S26: 8 | T26: 6 | U26: 6 | V26: 6 | W26: 6 | X26: 4 | Y26: 4 | Z26: 6 | AA26: 4 | AB26: 4 | AC26: 4 | AD26: 3 | AE26: 5 | AF26: 3 | AG26: 5 | AH26: 2 | AI26: 7 | AJ26: 6 | AK26: 3 | AL26: 2 | AM26: 3 | AN26: 5 | AO26: 2 | AP26: 2 | AQ26: 2 | AR26: 2 | AS26: 1 | AT26: 2 | AU26: 1 | AV26: 1 | AW26: 0 | AX26: 3 | AY26: 0 | AZ26: 3 | BA26: 4 | BB26: 2 | BC26: 2 | BD26: 1 | BE26: 0 | BF26: 1 | BG26: 3 | BH26: 3 | BI26: 2 | BJ26: 0 | BK26: 2 | BL26: 1 | BM26: 2 | BN26: 1 | BO26: 1 | BP26: 0 | BQ26: 1 | BR26: 0 | BS26: 3 | BT26: 0 | BU26: 0 | BV26: 0 | BW26: 3 | BX26: 0 | BY26: 2 | BZ26: 2 | CA26: 1 | CB26: 2 | CC26: 0 | CD26: 3 | CE26: 1 | CF26: 2 | CG26: 1 | CH26: 2 | CI26: 0 | CJ26: 0 | CK26: 2 | CL26: 0 | CM26: 1 | CN26: 0 | CO26: 1 | CP26: 1 | CQ26: 1 | CR26: 2 | CS26: 0 | DR26: =YEAR($A26) -> 2017
A27: =DATE(YEAR(A26),MONTH(A26)+1,DAY(A26)) -> 42767 | B27: 40 | C27: 55 | D27: 40 | E27: 34 | F27: 18 | G27: 21 | H27: 26 | I27: 13 | J27: 23 | K27: 16 | L27: 17 | M27: 17 | N27: 18 | O27: 11 | P27: 13 | Q27: 4 | R27: 6 | S27: 11 | T27: 5 | U27: 12 | V27: 7 | W27: 7 | X27: 9 | Y27: 4 | Z27: 11 | AA27: 7 | AB27: 7 | AC27: 4 | AD27: 8 | AE27: 6 | AF27: 4 | AG27: 7 | AH27: 2 | AI27: 3 | AJ27: 3 | AK27: 4 | AL27: 1 | AM27: 4 | AN27: 3 | AO27: 3 | AP27: 3 | AQ27: 4 | AR27: 4 | AS27: 0 | AT27: 4 | AU27: 4 | AV27: 5 | AW27: 1 | AX27: 2 | AY27: 4 | AZ27: 2 | BA27: 1 | BB27: 1 | BC27: 3 | BD27: 2 | BE27: 3 | BF27: 3 | BG27: 4 | BH27: 2 | BI27: 2 | BJ27: 4 | BK27: 3 | BL27: 1 | BM27: 1 | BN27: 3 | BO27: 2 | BP27: 2 | BQ27: 0 | BR27: 1 | BS27: 2 | BT27: 4 | BU27: 1 | BV27: 1 | BW27: 2 | BX27: 2 | BY27: 1 | BZ27: 0 | CA27: 0 | CB27: 0 | CC27: 3 | CD27: 1 | CE27: 1 | CF27: 1 | CG27: 1 | CH27: 1 | CI27: 1 | CJ27: 0 | CK27: 0 | CL27: 1 | CM27: 0 | CN27: 0 | CO27: 2 | CP27: 1 | CQ27: 0 | CR27: 0 | DR27: =YEAR($A27) -> 2017
A28: =DATE(YEAR(A27),MONTH(A27)+1,DAY(A27)) -> 42795 | B28: 47 | C28: 49 | D28: 39 | E28: 29 | F28: 30 | G28: 31 | H28: 24 | I28: 29 | J28: 12 | K28: 13 | L28: 19 | M28: 10 | N28: 15 | O28: 16 | P28: 18 | Q28: 14 | R28: 6 | S28: 8 | T28: 5 | U28: 13 | V28: 2 | W28: 7 | X28: 8 | Y28: 4 | Z28: 9 | AA28: 3 | AB28: 6 | AC28: 4 | AD28: 7 | AE28: 3 | AF28: 6 | AG28: 5 | AH28: 4 | AI28: 2 | AJ28: 2 | AK28: 2 | AL28: 4 | AM28: 3 | AN28: 1 | AO28: 0 | AP28: 6 | AQ28: 2 | AR28: 5 | AS28: 2 | AT28: 2 | AU28: 1 | AV28: 3 | AW28: 2 | AX28: 3 | AY28: 1 | AZ28: 3 | BA28: 2 | BB28: 1 | BC28: 0 | BD28: 4 | BE28: 1 | BF28: 1 | BG28: 0 | BH28: 0 | BI28: 0 | BJ28: 1 | BK28: 2 | BL28: 4 | BM28: 2 | BN28: 4 | BO28: 2 | BP28: 1 | BQ28: 1 | BR28: 1 | BS28: 0 | BT28: 0 | BU28: 1 | BV28: 1 | BW28: 1 | BX28: 0 | BY28: 0 | BZ28: 0 | CA28: 1 | CB28: 2 | CC28: 1 | CD28: 1 | CE28: 1 | CF28: 2 | CG28: 0 | CH28: 1 | CI28: 2 | CJ28: 0 | CK28: 2 | CL28: 1 | CM28: 0 | CN28: 0 | CO28: 1 | CP28: 0 | CQ28: 0 | DR28: =YEAR($A28) -> 2017
A29: =DATE(YEAR(A28),MONTH(A28)+1,DAY(A28)) -> 42826 | B29: 61 | C29: 91 | D29: 46 | E29: 46 | F29: 44 | G29: 32 | H29: 29 | I29: 20 | J29: 27 | K29: 25 | L29: 24 | M29: 20 | N29: 28 | O29: 19 | P29: 11 | Q29: 17 | R29: 19 | S29: 12 | T29: 8 | U29: 11 | V29: 12 | W29: 7 | X29: 11 | Y29: 3 | Z29: 7 | AA29: 11 | AB29: 6 | AC29: 8 | AD29: 8 | AE29: 6 | AF29: 6 | AG29: 5 | AH29: 5 | AI29: 3 | AJ29: 8 | AK29: 6 | AL29: 5 | AM29: 4 | AN29: 3 | AO29: 2 | AP29: 1 | AQ29: 2 | AR29: 5 | AS29: 5 | AT29: 1 | AU29: 2 | AV29: 2 | AW29: 4 | AX29: 2 | AY29: 1 | AZ29: 4 | BA29: 4 | BB29: 2 | BC29: 5 | BD29: 4 | BE29: 1 | BF29: 4 | BG29: 2 | BH29: 3 | BI29: 3 | BJ29: 0 | BK29: 3 | BL29: 0 | BM29: 4 | BN29: 1 | BO29: 1 | BP29: 3 | BQ29: 2 | BR29: 2 | BS29: 0 | BT29: 1 | BU29: 1 | BV29: 2 | BW29: 1 | BX29: 2 | BY29: 0 | BZ29: 1 | CA29: 1 | CB29: 0 | CC29: 2 | CD29: 0 | CE29: 0 | CF29: 1 | CG29: 2 | CH29: 3 | CI29: 3 | CJ29: 0 | CK29: 1 | CL29: 1 | CM29: 0 | CN29: 0 | CO29: 0 | CP29: 0 | DR29: =YEAR($A29) -> 2017
A30: =DATE(YEAR(A29),MONTH(A29)+1,DAY(A29)) -> 42856 | B30: 74 | C30: 80 | D30: 62 | E30: 53 | F30: 38 | G30: 39 | H30: 35 | I30: 33 | J30: 19 | K30: 17 | L30: 30 | M30: 20 | N30: 20 | O30: 12 | P30: 20 | Q30: 23 | R30: 14 | S30: 13 | T30: 21 | U30: 11 | V30: 6 | W30: 4 | X30: 10 | Y30: 6 | Z30: 10 | AA30: 7 | AB30: 6 | AC30: 5 | AD30: 9 | AE30: 5 | AF30: 5 | AG30: 10 | AH30: 4 | AI30: 5 | AJ30: 2 | AK30: 8 | AL30: 5 | AM30: 3 | AN30: 11 | AO30: 6 | AP30: 3 | AQ30: 2 | AR30: 12 | AS30: 2 | AT30: 2 | AU30: 4 | AV30: 2 | AW30: 3 | AX30: 3 | AY30: 0 | AZ30: 1 | BA30: 1 | BB30: 4 | BC30: 4 | BD30: 2 | BE30: 0 | BF30: 2 | BG30: 4 | BH30: 3 | BI30: 1 | BJ30: 2 | BK30: 4 | BL30: 4 | BM30: 1 | BN30: 4 | BO30: 4 | BP30: 1 | BQ30: 1 | BR30: 0 | BS30: 2 | BT30: 2 | BU30: 1 | BV30: 0 | BW30: 1 | BX30: 3 | BY30: 1 | BZ30: 0 | CA30: 2 | CB30: 1 | CC30: 0 | CD30: 1 | CE30: 2 | CF30: 1 | CG30: 4 | CH30: 1 | CI30: 3 | CJ30: 1 | CK30: 1 | CL30: 3 | CM30: 0 | CN30: 0 | CO30: 0 | DR30: =YEAR($A30) -> 2017
A31: =DATE(YEAR(A30),MONTH(A30)+1,DAY(A30)) -> 42887 | B31: 59 | C31: 103 | D31: 110 | E31: 62 | F31: 53 | G31: 39 | H31: 44 | I31: 25 | J31: 39 | K31: 29 | L31: 31 | M31: 23 | N31: 19 | O31: 19 | P31: 19 | Q31: 19 | R31: 12 | S31: 20 | T31: 11 | U31: 10 | V31: 8 | W31: 7 | X31: 11 | Y31: 8 | Z31: 9 | AA31: 11 | AB31: 6 | AC31: 9 | AD31: 8 | AE31: 8 | AF31: 6 | AG31: 12 | AH31: 2 | AI31: 5 | AJ31: 4 | AK31: 1 | AL31: 3 | AM31: 9 | AN31: 4 | AO31: 6 | AP31: 9 | AQ31: 7 | AR31: 2 | AS31: 5 | AT31: 5 | AU31: 6 | AV31: 1 | AW31: 0 | AX31: 5 | AY31: 1 | AZ31: 5 | BA31: 3 | BB31: 3 | BC31: 4 | BD31: 2 | BE31: 1 | BF31: 1 | BG31: 2 | BH31: 1 | BI31: 6 | BJ31: 3 | BK31: 6 | BL31: 1 | BM31: 1 | BN31: 1 | BO31: 5 | BP31: 2 | BQ31: 2 | BR31: 2 | BS31: 1 | BT31: 3 | BU31: 2 | BV31: 2 | BW31: 3 | BX31: 0 | BY31: 3 | BZ31: 0 | CA31: 1 | CB31: 2 | CC31: 1 | CD31: 0 | CE31: 0 | CF31: 2 | CG31: 1 | CH31: 1 | CI31: 0 | CJ31: 2 | CK31: 1 | CL31: 0 | CM31: 3 | CN31: 0 | DR31: =YEAR($A31) -> 2017
A32: =DATE(YEAR(A31),MONTH(A31)+1,DAY(A31)) -> 42917 | B32: 82 | C32: 149 | D32: 147 | E32: 104 | F32: 59 | G32: 46 | H32: 46 | I32: 42 | J32: 28 | K32: 42 | L32: 26 | M32: 27 | N32: 25 | O32: 27 | P32: 15 | Q32: 16 | R32: 14 | S32: 14 | T32: 17 | U32: 15 | V32: 12 | W32: 11 | X32: 12 | Y32: 12 | Z32: 8 | AA32: 7 | AB32: 4 | AC32: 8 | AD32: 10 | AE32: 9 | AF32: 8 | AG32: 3 | AH32: 4 | AI32: 2 | AJ32: 6 | AK32: 4 | AL32: 5 | AM32: 4 | AN32: 1 | AO32: 2 | AP32: 8 | AQ32: 4 | AR32: 0 | AS32: 4 | AT32: 1 | AU32: 4 | AV32: 3 | AW32: 3 | AX32: 3 | AY32: 2 | AZ32: 0 | BA32: 2 | BB32: 6 | BC32: 1 | BD32: 1 | BE32: 0 | BF32: 0 | BG32: 1 | BH32: 3 | BI32: 5 | BJ32: 4 | BK32: 3 | BL32: 1 | BM32: 2 | BN32: 3 | BO32: 0 | BP32: 2 | BQ32: 0 | BR32: 3 | BS32: 0 | BT32: 1 | BU32: 1 | BV32: 3 | BW32: 1 | BX32: 2 | BY32: 1 | BZ32: 1 | CA32: 2 | CB32: 1 | CC32: 1 | CD32: 1 | CE32: 1 | CF32: 1 | CG32: 2 | CH32: 0 | CI32: 1 | CJ32: 3 | CK32: 1 | CL32: 1 | CM32: 0 | DR32: =YEAR($A32) -> 2017
A33: =DATE(YEAR(A32),MONTH(A32)+1,DAY(A32)) -> 42948 | B33: 50 | C33: 112 | D33: 71 | E33: 84 | F33: 42 | G33: 31 | H33: 19 | I33: 20 | J33: 22 | K33: 17 | L33: 25 | M33: 25 | N33: 17 | O33: 22 | P33: 8 | Q33: 12 | R33: 8 | S33: 10 | T33: 5 | U33: 7 | V33: 4 | W33: 7 | X33: 7 | Y33: 8 | Z33: 2 | AA33: 3 | AB33: 7 | AC33: 4 | AD33: 5 | AE33: 2 | AF33: 5 | AG33: 4 | AH33: 5 | AI33: 1 | AJ33: 1 | AK33: 3 | AL33: 4 | AM33: 1 | AN33: 1 | AO33: 3 | AP33: 3 | AQ33: 0 | AR33: 2 | AS33: 5 | AT33: 0 | AU33: 2 | AV33: 3 | AW33: 2 | AX33: 1 | AY33: 1 | AZ33: 3 | BA33: 1 | BB33: 2 | BC33: 1 | BD33: 0 | BE33: 0 | BF33: 0 | BG33: 3 | BH33: 1 | BI33: 6 | BJ33: 2 | BK33: 1 | BL33: 0 | BM33: 1 | BN33: 0 | BO33: 1 | BP33: 4 | BQ33: 1 | BR33: 1 | BS33: 1 | BT33: 1 | BU33: 1 | BV33: 2 | BW33: 0 | BX33: 2 | BY33: 2 | BZ33: 0 | CA33: 1 | CB33: 0 | CC33: 0 | CD33: 1 | CE33: 0 | CF33: 0 | CG33: 0 | CH33: 0 | CI33: 0 | CJ33: 1 | CK33: 0 | CL33: 1 | DR33: =YEAR($A33) -> 2017
A34: =DATE(YEAR(A33),MONTH(A33)+1,DAY(A33)) -> 42979 | B34: 57 | C34: 116 | D34: 82 | E34: 100 | F34: 58 | G34: 46 | H34: 32 | I34: 24 | J34: 20 | K34: 22 | L34: 24 | M34: 16 | N34: 22 | O34: 16 | P34: 25 | Q34: 17 | R34: 15 | S34: 14 | T34: 9 | U34: 13 | V34: 10 | W34: 10 | X34: 13 | Y34: 5 | Z34: 10 | AA34: 7 | AB34: 7 | AC34: 5 | AD34: 3 | AE34: 9 | AF34: 7 | AG34: 10 | AH34: 5 | AI34: 6 | AJ34: 7 | AK34: 1 | AL34: 4 | AM34: 6 | AN34: 4 | AO34: 0 | AP34: 1 | AQ34: 4 | AR34: 4 | AS34: 2 | AT34: 1 | AU34: 1 | AV34: 3 | AW34: 1 | AX34: 0 | AY34: 0 | AZ34: 5 | BA34: 3 | BB34: 1 | BC34: 3 | BD34: 2 | BE34: 2 | BF34: 1 | BG34: 3 | BH34: 1 | BI34: 1 | BJ34: 1 | BK34: 1 | BL34: 0 | BM34: 4 | BN34: 1 | BO34: 0 | BP34: 0 | BQ34: 1 | BR34: 1 | BS34: 0 | BT34: 0 | BU34: 2 | BV34: 0 | BW34: 2 | BX34: 1 | BY34: 3 | BZ34: 0 | CA34: 0 | CB34: 0 | CC34: 1 | CD34: 0 | CE34: 0 | CF34: 0 | CG34: 0 | CH34: 0 | CI34: 0 | CJ34: 0 | CK34: 2 | DR34: =YEAR($A34) -> 2017
A35: =DATE(YEAR(A34),MONTH(A34)+1,DAY(A34)) -> 43009 | B35: 116 | C35: 205 | D35: 155 | E35: 153 | F35: 68 | G35: 67 | H35: 51 | I35: 46 | J35: 31 | K35: 53 | L35: 44 | M35: 41 | N35: 34 | O35: 28 | P35: 21 | Q35: 32 | R35: 25 | S35: 26 | T35: 16 | U35: 17 | V35: 12 | W35: 20 | X35: 8 | Y35: 16 | Z35: 17 | AA35: 11 | AB35: 13 | AC35: 9 | AD35: 10 | AE35: 8 | AF35: 8 | AG35: 7 | AH35: 2 | AI35: 12 | AJ35: 1 | AK35: 4 | AL35: 11 | AM35: 3 | AN35: 8 | AO35: 3 | AP35: 2 | AQ35: 6 | AR35: 4 | AS35: 3 | AT35: 3 | AU35: 6 | AV35: 4 | AW35: 4 | AX35: 6 | AY35: 4 | AZ35: 1 | BA35: 5 | BB35: 2 | BC35: 1 | BD35: 3 | BE35: 5 | BF35: 0 | BG35: 1 | BH35: 3 | BI35: 4 | BJ35: 6 | BK35: 3 | BL35: 3 | BM35: 1 | BN35: 3 | BO35: 2 | BP35: 1 | BQ35: 1 | BR35: 3 | BS35: 2 | BT35: 0 | BU35: 3 | BV35: 1 | BW35: 1 | BX35: 1 | BY35: 0 | BZ35: 0 | CA35: 1 | CB35: 0 | CC35: 2 | CD35: 0 | CE35: 3 | CF35: 1 | CG35: 0 | CH35: 2 | CI35: 1 | CJ35: 0 | DR35: =YEAR($A35) -> 2017
A36: =DATE(YEAR(A35),MONTH(A35)+1,DAY(A35)) -> 43040 | B36: 98 | C36: 160 | D36: 144 | E36: 136 | F36: 80 | G36: 43 | H36: 51 | I36: 41 | J36: 36 | K36: 41 | L36: 35 | M36: 30 | N36: 23 | O36: 26 | P36: 19 | Q36: 23 | R36: 26 | S36: 15 | T36: 17 | U36: 12 | V36: 14 | W36: 10 | X36: 11 | Y36: 6 | Z36: 9 | AA36: 14 | AB36: 7 | AC36: 3 | AD36: 6 | AE36: 9 | AF36: 6 | AG36: 8 | AH36: 6 | AI36: 10 | AJ36: 5 | AK36: 11 | AL36: 8 | AM36: 5 | AN36: 6 | AO36: 8 | AP36: 4 | AQ36: 7 | AR36: 6 | AS36: 1 | AT36: 3 | AU36: 2 | AV36: 8 | AW36: 3 | AX36: 3 | AY36: 5 | AZ36: 2 | BA36: 3 | BB36: 2 | BC36: 3 | BD36: 2 | BE36: 1 | BF36: 2 | BG36: 2 | BH36: 3 | BI36: 4 | BJ36: 4 | BK36: 3 | BL36: 3 | BM36: 2 | BN36: 3 | BO36: 2 | BP36: 3 | BQ36: 3 | BR36: 2 | BS36: 0 | BT36: 3 | BU36: 1 | BV36: 2 | BW36: 1 | BX36: 3 | BY36: 2 | BZ36: 2 | CA36: 1 | CB36: 2 | CC36: 2 | CD36: 0 | CE36: 0 | CF36: 0 | CG36: 5 | CH36: 1 | CI36: 3 | DR36: =YEAR($A36) -> 2017
A37: =DATE(YEAR(A36),MONTH(A36)+1,DAY(A36)) -> 43070 | B37: 94 | C37: 164 | D37: 175 | E37: 88 | F37: 65 | G37: 55 | H37: 48 | I37: 53 | J37: 33 | K37: 39 | L37: 29 | M37: 32 | N37: 29 | O37: 20 | P37: 18 | Q37: 25 | R37: 29 | S37: 20 | T37: 13 | U37: 19 | V37: 6 | W37: 9 | X37: 7 | Y37: 8 | Z37: 8 | AA37: 7 | AB37: 6 | AC37: 16 | AD37: 9 | AE37: 11 | AF37: 6 | AG37: 9 | AH37: 4 | AI37: 5 | AJ37: 4 | AK37: 7 | AL37: 4 | AM37: 5 | AN37: 7 | AO37: 5 | AP37: 3 | AQ37: 9 | AR37: 5 | AS37: 4 | AT37: 4 | AU37: 2 | AV37: 6 | AW37: 2 | AX37: 7 | AY37: 3 | AZ37: 1 | BA37: 7 | BB37: 1 | BC37: 2 | BD37: 5 | BE37: 2 | BF37: 2 | BG37: 4 | BH37: 1 | BI37: 2 | BJ37: 3 | BK37: 3 | BL37: 2 | BM37: 1 | BN37: 2 | BO37: 1 | BP37: 1 | BQ37: 1 | BR37: 0 | BS37: 1 | BT37: 3 | BU37: 1 | BV37: 3 | BW37: 4 | BX37: 4 | BY37: 2 | BZ37: 1 | CA37: 0 | CB37: 1 | CC37: 3 | CD37: 1 | CE37: 3 | CF37: 2 | CG37: 0 | CH37: 0 | DR37: =YEAR($A37) -> 2017
A38: =DATE(YEAR(A37),MONTH(A37)+1,DAY(A37)) -> 43101 | B38: 103 | C38: 234 | D38: 150 | E38: 117 | F38: 52 | G38: 61 | H38: 45 | I38: 67 | J38: 41 | K38: 32 | L38: 36 | M38: 31 | N38: 21 | O38: 29 | P38: 23 | Q38: 19 | R38: 18 | S38: 19 | T38: 20 | U38: 11 | V38: 13 | W38: 13 | X38: 11 | Y38: 7 | Z38: 9 | AA38: 7 | AB38: 5 | AC38: 4 | AD38: 10 | AE38: 4 | AF38: 6 | AG38: 4 | AH38: 7 | AI38: 5 | AJ38: 6 | AK38: 3 | AL38: 2 | AM38: 5 | AN38: 2 | AO38: 5 | AP38: 3 | AQ38: 6 | AR38: 4 | AS38: 4 | AT38: 4 | AU38: 3 | AV38: 5 | AW38: 2 | AX38: 3 | AY38: 2 | AZ38: 2 | BA38: 5 | BB38: 3 | BC38: 2 | BD38: 7 | BE38: 2 | BF38: 4 | BG38: 2 | BH38: 4 | BI38: 1 | BJ38: 1 | BK38: 1 | BL38: 7 | BM38: 1 | BN38: 3 | BO38: 1 | BP38: 0 | BQ38: 3 | BR38: 2 | BS38: 1 | BT38: 1 | BU38: 2 | BV38: 3 | BW38: 1 | BX38: 1 | BY38: 3 | BZ38: 1 | CA38: 0 | CB38: 0 | CC38: 1 | CD38: 0 | CE38: 1 | CF38: 1 | CG38: 2 | DR38: =YEAR($A38) -> 2018
A39: =DATE(YEAR(A38),MONTH(A38)+1,DAY(A38)) -> 43132 | B39: 111 | C39: 184 | D39: 139 | E39: 104 | F39: 64 | G39: 78 | H39: 51 | I39: 52 | J39: 48 | K39: 52 | L39: 30 | M39: 35 | N39: 28 | O39: 35 | P39: 31 | Q39: 27 | R39: 15 | S39: 20 | T39: 15 | U39: 19 | V39: 12 | W39: 16 | X39: 5 | Y39: 11 | Z39: 7 | AA39: 14 | AB39: 12 | AC39: 12 | AD39: 5 | AE39: 15 | AF39: 6 | AG39: 3 | AH39: 3 | AI39: 12 | AJ39: 6 | AK39: 8 | AL39: 8 | AM39: 4 | AN39: 9 | AO39: 3 | AP39: 1 | AQ39: 5 | AR39: 7 | AS39: 2 | AT39: 3 | AU39: 6 | AV39: 5 | AW39: 3 | AX39: 4 | AY39: 5 | AZ39: 3 | BA39: 3 | BB39: 2 | BC39: 4 | BD39: 0 | BE39: 6 | BF39: 0 | BG39: 3 | BH39: 2 | BI39: 4 | BJ39: 3 | BK39: 6 | BL39: 3 | BM39: 3 | BN39: 4 | BO39: 2 | BP39: 0 | BQ39: 2 | BR39: 0 | BS39: 2 | BT39: 0 | BU39: 2 | BV39: 3 | BW39: 0 | BX39: 2 | BY39: 2 | BZ39: 2 | CA39: 1 | CB39: 3 | CC39: 1 | CD39: 2 | CE39: 0 | CF39: 0 | DR39: =YEAR($A39) -> 2018
A40: =DATE(YEAR(A39),MONTH(A39)+1,DAY(A39)) -> 43160 | B40: 100 | C40: 219 | D40: 155 | E40: 108 | F40: 71 | G40: 70 | H40: 74 | I40: 56 | J40: 40 | K40: 32 | L40: 39 | M40: 32 | N40: 34 | O40: 23 | P40: 24 | Q40: 20 | R40: 22 | S40: 27 | T40: 21 | U40: 18 | V40: 8 | W40: 16 | X40: 21 | Y40: 15 | Z40: 16 | AA40: 7 | AB40: 11 | AC40: 11 | AD40: 11 | AE40: 6 | AF40: 6 | AG40: 7 | AH40: 11 | AI40: 6 | AJ40: 5 | AK40: 6 | AL40: 6 | AM40: 6 | AN40: 6 | AO40: 6 | AP40: 6 | AQ40: 5 | AR40: 6 | AS40: 8 | AT40: 5 | AU40: 4 | AV40: 1 | AW40: 6 | AX40: 3 | AY40: 2 | AZ40: 2 | BA40: 6 | BB40: 7 | BC40: 5 | BD40: 4 | BE40: 0 | BF40: 2 | BG40: 3 | BH40: 0 | BI40: 3 | BJ40: 3 | BK40: 5 | BL40: 1 | BM40: 3 | BN40: 1 | BO40: 1 | BP40: 1 | BQ40: 0 | BR40: 1 | BS40: 1 | BT40: 3 | BU40: 2 | BV40: 0 | BW40: 0 | BX40: 3 | BY40: 0 | BZ40: 2 | CA40: 1 | CB40: 0 | CC40: 2 | CD40: 2 | CE40: 0 | DR40: =YEAR($A40) -> 2018
...

Sheet Death_data
A1: 1st of Commencement month (DD/MM/YYYY) | B1: Claims in Month 1 | C1: Claims in Month 2 | D1: Claims in Month 3 | E1: Claims in Month 4 | F1: Claims in Month 5 | G1: Claims in Month 6 | H1: Claims in Month 7 | I1: Claims in Month 8 | J1: Claims in Month 9 | K1: Claims in Month 10 | L1: Claims in Month 11 | M1: Claims in Month 12 | N1: Claims in Year 2 | O1: Claims in Year 3 | P1: Claims in Year 4 | Q1: Claims in Year 5 | R1: Claims in Year 6 | S1: Claims in Year 7 | T1: Claims in Year 8 | U1: Claims in Year 9 | V1: Claims in Year 10
A2: 42005 | B2: 0 | C2: 0 | D2: 0 | E2: 0 | F2: 0 | G2: 0 | H2: 0 | I2: 0 | J2: 0 | K2: 0 | L2: 0 | M2: 0 | N2: 0 | O2: 0 | P2: 0 | Q2: 0 | R2: 0 | S2: 0 | T2: 0 | U2: 0 | V2: 0
A3: =DATE(YEAR(A2),MONTH(A2)+1,DAY(A2)) -> 42036 | B3: 0 | C3: 0 | D3: 0 | E3: 0 | F3: 0 | G3: 0 | H3: 0 | I3: 1 | J3: 0 | K3: 0 | L3: 0 | M3: 0 | N3: 0 | O3: 0 | P3: 0 | Q3: 0 | R3: 0 | S3: 0 | T3: 0 | U3: 0 | V3: 0
A4: =DATE(YEAR(A3),MONTH(A3)+1,DAY(A3)) -> 42064 | B4: 0 | C4: 0 | D4: 0 | E4: 0 | F4: 0 | G4: 0 | H4: 0 | I4: 1 | J4: 0 | K4: 0 | L4: 0 | M4: 0 | N4: 0 | O4: 0 | P4: 0 | Q4: 0 | R4: 0 | S4: 0 | T4: 0 | U4: 0 | V4: 0
A5: =DATE(YEAR(A4),MONTH(A4)+1,DAY(A4)) -> 42095 | B5: 0 | C5: 0 | D5: 1 | E5: 1 | F5: 0 | G5: 0 | H5: 0 | I5: 0 | J5: 0 | K5: 0 | L5: 0 | M5: 0 | N5: 0 | O5: 1 | P5: 0 | Q5: 0 | R5: 1 | S5: 0 | T5: 1 | U5: 0 | V5: 0
A6: =DATE(YEAR(A5),MONTH(A5)+1,DAY(A5)) -> 42125 | B6: 0 | C6: 0 | D6: 0 | E6: 1 | F6: 0 | G6: 0 | H6: 0 | I6: 0 | J6: 1 | K6: 0 | L6: 0 | M6: 0 | N6: 0 | O6: 0 | P6: 0 | Q6: 0 | R6: 1 | S6: 0 | T6: 0 | U6: 0 | V6: 0
A7: =DATE(YEAR(A6),MONTH(A6)+1,DAY(A6)) -> 42156 | B7: 0 | C7: 0 | D7: 0 | E7: 0 | F7: 0 | G7: 0 | H7: 0 | I7: 0 | J7: 0 | K7: 0 | L7: 0 | M7: 1 | N7: 1 | O7: 2 | P7: 1 | Q7: 0 | R7: 0 | S7: 0 | T7: 1 | U7: 0 | V7: 0
A8: =DATE(YEAR(A7),MONTH(A7)+1,DAY(A7)) -> 42186 | B8: 1 | C8: 0 | D8: 0 | E8: 1 | F8: 0 | G8: 0 | H8: 0 | I8: 0 | J8: 0 | K8: 0 | L8: 0 | M8: 0 | N8: 0 | O8: 1 | P8: 2 | Q8: 1 | R8: 0 | S8: 0 | T8: 0 | U8: 1 | V8: 0
A9: =DATE(YEAR(A8),MONTH(A8)+1,DAY(A8)) -> 42217 | B9: 0 | C9: 1 | D9: 0 | E9: 1 | F9: 0 | G9: 0 | H9: 0 | I9: 0 | J9: 0 | K9: 0 | L9: 0 | M9: 1 | N9: 1 | O9: 0 | P9: 1 | Q9: 0 | R9: 0 | S9: 2 | T9: 1 | U9: 1 | V9: 0
A10: =DATE(YEAR(A9),MONTH(A9)+1,DAY(A9)) -> 42248 | B10: 0 | C10: 0 | D10: 0 | E10: 1 | F10: 0 | G10: 0 | H10: 0 | I10: 0 | J10: 0 | K10: 0 | L10: 0 | M10: 0 | N10: 2 | O10: 2 | P10: 0 | Q10: 1 | R10: 1 | S10: 1 | T10: 2 | U10: 0 | V10: 0
A11: =DATE(YEAR(A10),MONTH(A10)+1,DAY(A10)) -> 42278 | B11: 0 | C11: 0 | D11: 0 | E11: 0 | F11: 0 | G11: 0 | H11: 0 | I11: 0 | J11: 0 | K11: 0 | L11: 0 | M11: 0 | N11: 0 | O11: 1 | P11: 2 | Q11: 0 | R11: 0 | S11: 0 | T11: 2 | U11: 1 | V11: 0
A12: =DATE(YEAR(A11),MONTH(A11)+1,DAY(A11)) -> 42309 | B12: 1 | C12: 0 | D12: 0 | E12: 0 | F12: 1 | G12: 0 | H12: 1 | I12: 0 | J12: 0 | K12: 0 | L12: 0 | M12: 0 | N12: 0 | O12: 0 | P12: 0 | Q12: 0 | R12: 0 | S12: 1 | T12: 0 | U12: 0 | V12: 0
A13: =DATE(YEAR(A12),MONTH(A12)+1,DAY(A12)) -> 42339 | B13: 0 | C13: 0 | D13: 0 | E13: 2 | F13: 0 | G13: 0 | H13: 0 | I13: 0 | J13: 0 | K13: 0 | L13: 0 | M13: 0 | N13: 1 | O13: 1 | P13: 1 | Q13: 0 | R13: 0 | S13: 0 | T13: 1 | U13: 0 | V13: 1
A14: =DATE(YEAR(A13),MONTH(A13)+1,DAY(A13)) -> 42370 | B14: 1 | C14: 0 | D14: 0 | E14: 0 | F14: 0 | G14: 0 | H14: 1 | I14: 0 | J14: 0 | K14: 0 | L14: 1 | M14: 0 | N14: 0 | O14: 1 | P14: 0 | Q14: 0 | R14: 0 | S14: 0 | T14: 0 | U14: 0
A15: =DATE(YEAR(A14),MONTH(A14)+1,DAY(A14)) -> 42401 | B15: 0 | C15: 0 | D15: 0 | E15: 1 | F15: 0 | G15: 0 | H15: 0 | I15: 1 | J15: 0 | K15: 0 | L15: 0 | M15: 0 | N15: 1 | O15: 0 | P15: 0 | Q15: 1 | R15: 0 | S15: 0 | T15: 0 | U15: 0
A16: =DATE(YEAR(A15),MONTH(A15)+1,DAY(A15)) -> 42430 | B16: 0 | C16: 1 | D16: 0 | E16: 0 | F16: 0 | G16: 0 | H16: 0 | I16: 0 | J16: 0 | K16: 0 | L16: 0 | M16: 0 | N16: 2 | O16: 2 | P16: 0 | Q16: 0 | R16: 1 | S16: 0 | T16: 0 | U16: 0
A17: =DATE(YEAR(A16),MONTH(A16)+1,DAY(A16)) -> 42461 | B17: 0 | C17: 0 | D17: 0 | E17: 0 | F17: 0 | G17: 0 | H17: 1 | I17: 0 | J17: 0 | K17: 0 | L17: 0 | M17: 0 | N17: 1 | O17: 0 | P17: 0 | Q17: 0 | R17: 0 | S17: 0 | T17: 0 | U17: 1
A18: =DATE(YEAR(A17),MONTH(A17)+1,DAY(A17)) -> 42491 | B18: 1 | C18: 0 | D18: 0 | E18: 0 | F18: 0 | G18: 0 | H18: 0 | I18: 0 | J18: 0 | K18: 1 | L18: 0 | M18: 0 | N18: 0 | O18: 2 | P18: 0 | Q18: 2 | R18: 1 | S18: 0 | T18: 0 | U18: 1
A19: =DATE(YEAR(A18),MONTH(A18)+1,DAY(A18)) -> 42522 | B19: 4 | C19: 0 | D19: 1 | E19: 0 | F19: 0 | G19: 0 | H19: 0 | I19: 0 | J19: 0 | K19: 0 | L19: 0 | M19: 0 | N19: 1 | O19: 1 | P19: 0 | Q19: 0 | R19: 0 | S19: 0 | T19: 1 | U19: 0
A20: =DATE(YEAR(A19),MONTH(A19)+1,DAY(A19)) -> 42552 | B20: 0 | C20: 0 | D20: 0 | E20: 0 | F20: 0 | G20: 0 | H20: 0 | I20: 1 | J20: 0 | K20: 0 | L20: 0 | M20: 0 | N20: 0 | O20: 1 | P20: 0 | Q20: 0 | R20: 1 | S20: 0 | T20: 2 | U20: 0
A21: =DATE(YEAR(A20),MONTH(A20)+1,DAY(A20)) -> 42583 | B21: 0 | C21: 1 | D21: 0 | E21: 0 | F21: 0 | G21: 0 | H21: 0 | I21: 0 | J21: 0 | K21: 0 | L21: 0 | M21: 1 | N21: 1 | O21: 2 | P21: 1 | Q21: 0 | R21: 0 | S21: 0 | T21: 1 | U21: 0
A22: =DATE(YEAR(A21),MONTH(A21)+1,DAY(A21)) -> 42614 | B22: 0 | C22: 0 | D22: 0 | E22: 0 | F22: 1 | G22: 1 | H22: 0 | I22: 0 | J22: 0 | K22: 0 | L22: 0 | M22: 0 | N22: 2 | O22: 1 | P22: 0 | Q22: 1 | R22: 0 | S22: 0 | T22: 1 | U22: 0
A23: =DATE(YEAR(A22),MONTH(A22)+1,DAY(A22)) -> 42644 | B23: 1 | C23: 0 | D23: 1 | E23: 0 | F23: 0 | G23: 0 | H23: 1 | I23: 0 | J23: 1 | K23: 0 | L23: 0 | M23: 0 | N23: 0 | O23: 0 | P23: 0 | Q23: 0 | R23: 0 | S23: 0 | T23: 1 | U23: 1
A24: =DATE(YEAR(A23),MONTH(A23)+1,DAY(A23)) -> 42675 | B24: 0 | C24: 0 | D24: 0 | E24: 2 | F24: 0 | G24: 0 | H24: 0 | I24: 0 | J24: 0 | K24: 0 | L24: 0 | M24: 0 | N24: 0 | O24: 1 | P24: 1 | Q24: 0 | R24: 1 | S24: 0 | T24: 0 | U24: 0
A25: =DATE(YEAR(A24),MONTH(A24)+1,DAY(A24)) -> 42705 | B25: 0 | C25: 0 | D25: 1 | E25: 0 | F25: 1 | G25: 0 | H25: 0 | I25: 1 | J25: 0 | K25: 0 | L25: 0 | M25: 0 | N25: 1 | O25: 0 | P25: 0 | Q25: 2 | R25: 1 | S25: 0 | T25: 0 | U25: 0
A26: =DATE(YEAR(A25),MONTH(A25)+1,DAY(A25)) -> 42736 | B26: 0 | C26: 0 | D26: 1 | E26: 0 | F26: 0 | G26: 0 | H26: 0 | I26: 0 | J26: 0 | K26: 0 | L26: 0 | M26: 1 | N26: 2 | O26: 1 | P26: 1 | Q26: 0 | R26: 2 | S26: 2 | T26: 0
A27: =DATE(YEAR(A26),MONTH(A26)+1,DAY(A26)) -> 42767 | B27: 0 | C27: 1 | D27: 0 | E27: 0 | F27: 0 | G27: 1 | H27: 0 | I27: 0 | J27: 0 | K27: 0 | L27: 0 | M27: 0 | N27: 0 | O27: 1 | P27: 0 | Q27: 0 | R27: 0 | S27: 1 | T27: 0
A28: =DATE(YEAR(A27),MONTH(A27)+1,DAY(A27)) -> 42795 | B28: 0 | C28: 1 | D28: 0 | E28: 1 | F28: 0 | G28: 0 | H28: 0 | I28: 0 | J28: 1 | K28: 0 | L28: 0 | M28: 0 | N28: 4 | O28: 1 | P28: 1 | Q28: 1 | R28: 1 | S28: 1 | T28: 1
A29: =DATE(YEAR(A28),MONTH(A28)+1,DAY(A28)) -> 42826 | B29: 1 | C29: 0 | D29: 0 | E29: 0 | F29: 0 | G29: 0 | H29: 0 | I29: 0 | J29: 0 | K29: 0 | L29: 1 | M29: 0 | N29: 0 | O29: 0 | P29: 0 | Q29: 0 | R29: 0 | S29: 0 | T29: 0
A30: =DATE(YEAR(A29),MONTH(A29)+1,DAY(A29)) -> 42856 | B30: 0 | C30: 0 | D30: 0 | E30: 0 | F30: 0 | G30: 0 | H30: 0 | I30: 0 | J30: 0 | K30: 0 | L30: 0 | M30: 0 | N30: 0 | O30: 4 | P30: 0 | Q30: 2 | R30: 0 | S30: 0 | T30: 2
A31: =DATE(YEAR(A30),MONTH(A30)+1,DAY(A30)) -> 42887 | B31: 1 | C31: 0 | D31: 0 | E31: 2 | F31: 1 | G31: 0 | H31: 0 | I31: 0 | J31: 0 | K31: 0 | L31: 0 | M31: 0 | N31: 2 | O31: 3 | P31: 0 | Q31: 1 | R31: 1 | S31: 2 | T31: 1
A32: =DATE(YEAR(A31),MONTH(A31)+1,DAY(A31)) -> 42917 | B32: 0 | C32: 1 | D32: 0 | E32: 0 | F32: 0 | G32: 1 | H32: 0 | I32: 1 | J32: 0 | K32: 0 | L32: 0 | M32: 0 | N32: 1 | O32: 0 | P32: 0 | Q32: 0 | R32: 0 | S32: 0 | T32: 0
A33: =DATE(YEAR(A32),MONTH(A32)+1,DAY(A32)) -> 42948 | B33: 1 | C33: 0 | D33: 2 | E33: 0 | F33: 0 | G33: 0 | H33: 0 | I33: 0 | J33: 0 | K33: 1 | L33: 0 | M33: 0 | N33: 2 | O33: 4 | P33: 1 | Q33: 1 | R33: 0 | S33: 1 | T33: 0
A34: =DATE(YEAR(A33),MONTH(A33)+1,DAY(A33)) -> 42979 | B34: 0 | C34: 0 | D34: 1 | E34: 0 | F34: 1 | G34: 1 | H34: 0 | I34: 1 | J34: 0 | K34: 0 | L34: 0 | M34: 0 | N34: 2 | O34: 2 | P34: 1 | Q34: 2 | R34: 0 | S34: 1 | T34: 1
A35: =DATE(YEAR(A34),MONTH(A34)+1,DAY(A34)) -> 43009 | B35: 0 | C35: 0 | D35: 0 | E35: 0 | F35: 1 | G35: 0 | H35: 0 | I35: 0 | J35: 0 | K35: 0 | L35: 0 | M35: 0 | N35: 4 | O35: 3 | P35: 0 | Q35: 0 | R35: 2 | S35: 0 | T35: 2
A36: =DATE(YEAR(A35),MONTH(A35)+1,DAY(A35)) -> 43040 | B36: 0 | C36: 0 | D36: 0 | E36: 0 | F36: 0 | G36: 0 | H36: 1 | I36: 0 | J36: 0 | K36: 0 | L36: 0 | M36: 0 | N36: 2 | O36: 2 | P36: 3 | Q36: 2 | R36: 1 | S36: 1 | T36: 0
A37: =DATE(YEAR(A36),MONTH(A36)+1,DAY(A36)) -> 43070 | B37: 0 | C37: 1 | D37: 0 | E37: 0 | F37: 0 | G37: 0 | H37: 0 | I37: 0 | J37: 0 | K37: 0 | L37: 0 | M37: 0 | N37: 8 | O37: 3 | P37: 2 | Q37: 0 | R37: 2 | S37: 1 | T37: 1
A38: =DATE(YEAR(A37),MONTH(A37)+1,DAY(A37)) -> 43101 | B38: 0 | C38: 0 | D38: 1 | E38: 0 | F38: 0 | G38: 0 | H38: 0 | I38: 0 | J38: 0 | K38: 0 | L38: 0 | M38: 0 | N38: 3 | O38: 2 | P38: 1 | Q38: 0 | R38: 2 | S38: 1
A39: =DATE(YEAR(A38),MONTH(A38)+1,DAY(A38)) -> 43132 | B39: 0 | C39: 0 | D39: 1 | E39: 1 | F39: 1 | G39: 2 | H39: 0 | I39: 0 | J39: 0 | K39: 0 | L39: 1 | M39: 0 | N39: 2 | O39: 4 | P39: 5 | Q39: 1 | R39: 0 | S39: 3
A40: =DATE(YEAR(A39),MONTH(A39)+1,DAY(A39)) -> 43160 | B40: 0 | C40: 0 | D40: 1 | E40: 1 | F40: 0 | G40: 0 | H40: 0 | I40: 1 | J40: 0 | K40: 0 | L40: 1 | M40: 0 | N40: 5 | O40: 4 | P40: 3 | Q40: 0 | R40: 2 | S40: 2
...

Sheet Inception_data
A1: 1st of Commencement month (DD/MM/YYYY) | B1: Policies incepted
A2: 42005 | B2: 1086
A3: =DATE(YEAR(A2),MONTH(A2)+1,DAY(A2)) -> 42036 | B3: 1156
A4: =DATE(YEAR(A3),MONTH(A3)+1,DAY(A3)) -> 42064 | B4: 1072
A5: =DATE(YEAR(A4),MONTH(A4)+1,DAY(A4)) -> 42095 | B5: 1112
A6: =DATE(YEAR(A5),MONTH(A5)+1,DAY(A5)) -> 42125 | B6: 1031
A7: =DATE(YEAR(A6),MONTH(A6)+1,DAY(A6)) -> 42156 | B7: 895
A8: =DATE(YEAR(A7),MONTH(A7)+1,DAY(A7)) -> 42186 | B8: 803
A9: =DATE(YEAR(A8),MONTH(A8)+1,DAY(A8)) -> 42217 | B9: 768
A10: =DATE(YEAR(A9),MONTH(A9)+1,DAY(A9)) -> 42248 | B10: 783
A11: =DATE(YEAR(A10),MONTH(A10)+1,DAY(A10)) -> 42278 | B11: 1061
A12: =DATE(YEAR(A11),MONTH(A11)+1,DAY(A11)) -> 42309 | B12: 987
A13: =DATE(YEAR(A12),MONTH(A12)+1,DAY(A12)) -> 42339 | B13: 903
A14: =DATE(YEAR(A13),MONTH(A13)+1,DAY(A13)) -> 42370 | B14: 932
... A121: =DATE(YEAR(A120),MONTH(A120)+1,DAY(A120)) -> 45627 | B121: 134

Sheet Policies_In-Force
A1: 1st of Commencement month (DD/MM/YYYY) | B1: Policies incepted in month 1 | C1: Policies IF at start of Month 2 | D1: Policies IF at start of Month 3 | E1: Policies IF at start of Month 4 | F1: Policies IF at start of Month 5 | G1: Policies IF at start of Month 6 | H1: Policies IF at start of Month 7 | I1: Policies IF at start of Month 8 | J1: Policies IF at start of Month 9 | K1: Policies IF at start of Month 10 | L1: Policies IF at start of Month 11 | M1: Policies IF at start of Month 12 | N1: Policies IF at start of Year 2 | O1: Policies IF at start of Year 3 | P1: Policies IF at start of Year 4 | Q1: Policies IF at start of Year 5 | R1: Policies IF at start of Year 6 | S1: Policies IF at start of Year 7 | T1: Policies IF at start of Year 8 | U1: Policies IF at start of Year 9 | V1: Policies IF at start of Year 10 | W1: Policies IF at start of Year 11
A2: 42005 | B2: =Inception_data!B2 -> 1086 | C2: =B2-SUM(Lapse_data!B2,Death_data!B2) -> 1027 | D2: =C2-SUM(Lapse_data!C2,Death_data!C2) -> 929 | E2: =D2-SUM(Lapse_data!D2,Death_data!D2) -> 873 | F2: =E2-SUM(Lapse_data!E2,Death_data!E2) -> 794 | G2: =F2-SUM(Lapse_data!F2,Death_data!F2) -> 736 | H2: =G2-SUM(Lapse_data!G2,Death_data!G2) -> 702 | I2: =H2-SUM(Lapse_data!H2,Death_data!H2) -> 660 | J2: =I2-SUM(Lapse_data!I2,Death_data!I2) -> 628 | ... N2: =M2-SUM(Lapse_data!M2,Death_data!M2) -> 529 | O2: =N2 - SUM(Lapse_data!N2:Y2, Death_data!N2) -> 376 | P2: =O2 - SUM(Lapse_data!Z2:AK2, Death_data!O2) -> 301 | Q2: =P2 - SUM(Lapse_data!AL2:AW2, Death_data!P2) -> 227 | R2: =Q2 - SUM(Lapse_data!AX2:BI2, Death_data!Q2) -> 183 | S2: =R2 - SUM(Lapse_data!BJ2:BU2, Death_data!R2) -> 155 | T2: =S2 - SUM(Lapse_data!BV2:CG2, Death_data!S2) -> 128 | U2: =T2 - SUM(Lapse_data!CH2:CS2, Death_data!T2) -> 110 | V2: =U2 - SUM(Lapse_data!CT2:DE2, Death_data!U2) -> 103 | W2: =V2 - SUM(Lapse_data!DF2:DQ2, Death_data!V2) -> 94
A3: =DATE(YEAR(A2),MONTH(A2)+1,DAY(A2)) -> 42036 | B3: =Inception_data!B3 -> 1156 | C3: =B3-SUM(Lapse_data!B3,Death_data!B3) -> 1102 | D3: =C3-SUM(Lapse_data!C3,Death_data!C3) -> 997 | E3: =D3-SUM(Lapse_data!D3,Death_data!D3) -> 924 | F3: =E3-SUM(Lapse_data!E3,Death_data!E3) -> 853 | G3: =F3-SUM(Lapse_data!F3,Death_data!F3) -> 804 | H3: =G3-SUM(Lapse_data!G3,Death_data!G3) -> 753 | I3: =H3-SUM(Lapse_data!H3,Death_data!H3) -> 705 | J3: =I3-SUM(Lapse_data!I3,Death_data!I3) -> 670 | ... N3: =M3-SUM(Lapse_data!M3,Death_data!M3) -> 574 | O3: =N3 - SUM(Lapse_data!N3:Y3, Death_data!N3) -> 385 | P3: =O3 - SUM(Lapse_data!Z3:AK3, Death_data!O3) -> 278 | Q3: =P3 - SUM(Lapse_data!AL3:AW3, Death_data!P3) -> 219 | R3: =Q3 - SUM(Lapse_data!AX3:BI3, Death_data!Q3) -> 173 | S3: =R3 - SUM(Lapse_data!BJ3:BU3, Death_data!R3) -> 144 | T3: =S3 - SUM(Lapse_data!BV3:CG3, Death_data!S3) -> 131 | U3: =T3 - SUM(Lapse_data!CH3:CS3, Death_data!T3) -> 113 | V3: =U3 - SUM(Lapse_data!CT3:DE3, Death_data!U3) -> 102 | W3: =V3 - SUM(Lapse_data!DF3:DQ3, Death_data!V3) -> 90
A4: =DATE(YEAR(A3),MONTH(A3)+1,DAY(A3)) -> 42064 | B4: =Inception_data!B4 -> 1072 | C4: =B4-SUM(Lapse_data!B4,Death_data!B4) -> 1024 | D4: =C4-SUM(Lapse_data!C4,Death_data!C4) -> 930 | E4: =D4-SUM(Lapse_data!D4,Death_data!D4) -> 870 | F4: =E4-SUM(Lapse_data!E4,Death_data!E4) -> 809 | G4: =F4-SUM(Lapse_data!F4,Death_data!F4) -> 766 | H4: =G4-SUM(Lapse_data!G4,Death_data!G4) -> 726 | I4: =H4-SUM(Lapse_data!H4,Death_data!H4) -> 691 | J4: =I4-SUM(Lapse_data!I4,Death_data!I4) -> 656 | ... N4: =M4-SUM(Lapse_data!M4,Death_data!M4) -> 574 | O4: =N4 - SUM(Lapse_data!N4:Y4, Death_data!N4) -> 375 | P4: =O4 - SUM(Lapse_data!Z4:AK4, Death_data!O4) -> 277 | Q4: =P4 - SUM(Lapse_data!AL4:AW4, Death_data!P4) -> 211 | R4: =Q4 - SUM(Lapse_data!AX4:BI4, Death_data!Q4) -> 174 | S4: =R4 - SUM(Lapse_data!BJ4:BU4, Death_data!R4) -> 140 | T4: =S4 - SUM(Lapse_data!BV4:CG4, Death_data!S4) -> 125 | U4: =T4 - SUM(Lapse_data!CH4:CS4, Death_data!T4) -> 114 | V4: =U4 - SUM(Lapse_data!CT4:DE4, Death_data!U4) -> 102 | W4: =V4 - SUM(Lapse_data!DF4:DQ4, Death_data!V4) -> 97
A5: =DATE(YEAR(A4),MONTH(A4)+1,DAY(A4)) -> 42095 | B5: =Inception_data!B5 -> 1112 | C5: =B5-SUM(Lapse_data!B5,Death_data!B5) -> 1044 | D5: =C5-SUM(Lapse_data!C5,Death_data!C5) -> 954 | E5: =D5-SUM(Lapse_data!D5,Death_data!D5) -> 895 | F5: =E5-SUM(Lapse_data!E5,Death_data!E5) -> 831 | G5: =F5-SUM(Lapse_data!F5,Death_data!F5) -> 800 | H5: =G5-SUM(Lapse_data!G5,Death_data!G5) -> 739 | I5: =H5-SUM(Lapse_data!H5,Death_data!H5) -> 704 | J5: =I5-SUM(Lapse_data!I5,Death_data!I5) -> 670 | ... N5: =M5-SUM(Lapse_data!M5,Death_data!M5) -> 574 | O5: =N5 - SUM(Lapse_data!N5:Y5, Death_data!N5) -> 400 | P5: =O5 - SUM(Lapse_data!Z5:AK5, Death_data!O5) -> 307 | Q5: =P5 - SUM(Lapse_data!AL5:AW5, Death_data!P5) -> 247 | R5: =Q5 - SUM(Lapse_data!AX5:BI5, Death_data!Q5) -> 207 | S5: =R5 - SUM(Lapse_data!BJ5:BU5, Death_data!R5) -> 172 | T5: =S5 - SUM(Lapse_data!BV5:CG5, Death_data!S5) -> 148 | U5: =T5 - SUM(Lapse_data!CH5:CS5, Death_data!T5) -> 121 | V5: =U5 - SUM(Lapse_data!CT5:DE5, Death_data!U5) -> 107 | W5: =V5 - SUM(Lapse_data!DF5:DQ5, Death_data!V5) -> 100
